Workbook

Sheet BCQT 2023
A1: LIÊN ĐOÀN LAO ĐỘNG QUẬN TÂN PHÚ | E1: Mẫu: B07-TLĐ
A2: Công đoàn cơ sở: CTY TNHH TKXD & TM Hưng Phát | E2: (Ban hành kèm theo hướng dẫn
A3: Địa chỉ: 153G Lũy Bán Bích, P. Tân Thới Hòa, Q. Tân Phú, TP. HCM | E3: số 47 ngày 30/12/2021 của Tổng Liên đoàn)
A4: BÁO CÁO QUYẾT TOÁN THU, CHI TÀI CHÍNH CÔNG ĐOÀN
A5: Năm 2023
A6: A- CÁC CHỈ TIÊU CƠ BẢN
A7: - Số lao động Đóng KPCĐ: 10 người | C7: - Quỹ lương đóng KPCĐ: 60,090,000 đồng
A8: - Số đoàn viên: 10 người | C8: - Quỹ lương đóng ĐPCĐ: 60,090,000 đồng
A9: - Số cán bộ CĐ chuyên trách: 3 người
A10: B- CÁC CHỈ TIÊU THU CHI TÀI CHÍNH CÔNG ĐOÀN | F10: Đơn vị tính: đồng
A11: TT | B11: NỘI DUNG | C11: Mục lục TCCĐ (Mã số) | D11: Dự toán được giao | E11: Quyết toán năm | F11: Cấp trên duyệt
A12: I | B12: TÍCH LŨY TÀI CHÍNH ĐẦU KỲ | C12: 10 | E12: 15620760
A13: II | B13: PHẦN THU
A14: 2.1 | B14: Đoàn phí công đoàn | C14: 22 | E14: 13294800
A15: 2.2 | B15: Kinh phí công đoàn | C15: 23
A16: 2.3 | B16: Ngân sách nhà nước cấp hỗ trợ | C16: 24
A17: 2.4 | B17: Các khoản thu khác | C17: 25
B18: - Chuyên môn hỗ trợ | C18: 25.01
B19: - Thu khác | C19: 25.02 | E19: 50
B20: CỘNG THU TÀI CHÍNH CÔNG ĐOÀN | E20: =SUM(E14:E19) -> 13294850
A21: 2.5 | B21: Tài chính công đoàn cấp trên cấp | C21: 28
B22: a- Kinh phí công đoàn cấp trên cấp theo phân phối | C22: 28.01
B23: b- Tài chính công đoàn cấp trên cấp hỗ trợ | C23: 28.02
A24: 2.6 | B24: Nhận bàn giao tài chính | C24: 40
A25: 2.7 | B25: Các khoản khác tăng nguồn tài chính công đoàn | C25: 47
B26: TỔNG CỘNG THU | E26: =SUM(E20:E25) -> 13294850
A27: III | B27: PHẦN CHI
A28: 3.1 | B28: Chi bảo vệ, chăm lo đoàn viên và người lao động | C28: 31 | E28: 13700000
A29: 3.2 | B29: Chi tuyên truyền, đào tạo đoàn viên và người lao động | C29: 32
A30: 3.3 | B30: Chi quản lý hành chính | C30: 33 | E30: 1585000
A31: 3.4 | B31: Chi lương, phụ cấp và các khoản phải nộp theo lương | C31: 34
B32: a- Lương, phụ cấp... của cán bộ trong biên chế | C32: 34.01 | E32: 2454900
B33: b- Phụ cấp cán bộ công đoàn | C33: 34.02
B34: c- Các khoản phải nộp theo lương | C34: 34.03
A35: 3.5 | B35: Chi khác | C35: 37
B36: CỘNG CHI TÀI CHÍNH CÔNG ĐOÀN | E36: =SUM(E28:E35) -> 17739900
A37: 3.6 | B37: ĐPCĐ đã nộp cấp trên quản lý trực tiếp | C37: 39
A38: 3.7 | B38: Bàn giao tài chính công đoàn | C38: 42
A39: 3.8 | B39: Các khoản khác giảm nguồn tài chính công đoàn | C39: 48
B40: TỔNG CỘNG CHI | E40: =+E36+E37 -> 17739900
...

Sheet SỔ TM 2023
A1: LIÊN ĐOÀN LAO ĐỘNG QUẬN TÂN PHÚ | F1: Mẫu số S12-H
A2: Công đoàn cơ sở: CTY TNHH TKXD & TM Hưng Phát | F2: (Ban hành kèm theo Thông tư số 107/2017/TT-BTC
F3: ngày 10/10/2017 của Bộ Tài chính)
A4: SỔ QUỸ TIỀN MẶT
A5: NĂM 2023
A7: SỐ HIỆU CHỨNG TỪ | D7: DIỄN GIẢI | E7: SỐ TIỀN | H7: Ghi chú
A8: Ngày tháng | B8: Thu | C8: Chi | E8: Thu | F8: Chi | G8: Tồn quỹ
A9: A | B9: B | C9: C | D9: E | E9: 1 | F9: 2 | G9: 3 | H9: G
D10: Số dư đầu kỳ | G10: 15594300
A11: 44928 | B11: PT2023/01 | D11: Thu bổ sung đoàn phí công đoàn 1 % năm 2021 | E11: 6984000 | G11: =+G10+E11-F11 -> 22578300
A12: 44928 | C12: PC2023/01 | D12: Chi mừng sinh nhật đoàn viên Trịnh Xà Vong | F12: 200000 | G12: =+G11+E12-F12 -> 22378300
A13: 44936 | C13: PC2023/02 | D13: Chi mừng tết âm lịch cho đoàn viên (10 người) | F13: 5000000 | G13: =+G12+E13-F13 -> 17378300
A14: 44942 | C14: PC2023/03 | D14: Chi mừng sinh nhật đoàn viên Nguyễn Thị Ngọc Trinh | F14: 200000 | G14: =+G13+E14-F14 -> 17178300
A15: 44955 | C15: PC2023/04 | D15: Chi mừng đoàn viên Ngô Thị Bích Ngọc sinh con | F15: 500000 | G15: =+G14+E15-F15 -> 16678300
A16: 44993 | C16: PC2023/05 | D16: Chi mừng lễ 8/3 cho 4 đoàn viên nữ | F16: 800000 | G16: =+G15+E16-F16 -> 15878300
A17: 45019 | C17: PC2023/06 | D17: Chi mừng sinh nhật đoàn viên Nguyễn Quốc Đạt | F17: 200000 | G17: =+G16+E17-F17 -> 15678300
A18: 45032 | C18: PC2023/07 | D18: Chi mừng sinh nhật đoàn viên Ngô Thị Bích Ngọc | F18: 200000 | G18: =+G17+E18-F18 -> 15478300
A19: 45033 | C19: PC2023/08 | D19: Chi mừng sinh nhật đoàn viên Nguyễn Bá Quân | F19: 200000 | G19: =+G18+E19-F19 -> 15278300
A20: 45044 | C20: PC2023/09 | D20: Chi mừng lễ 30/4 và 1/5 (10 đoàn viên) | F20: 2000000 | G20: =+G19+E20-F20 -> 13278300
A21: 45048 | C21: PC2023/10 | D21: Chi mừng sinh nhật đoàn viên Nguyễn Kiên Hải | F21: 200000 | G21: =+G20+E21-F21 -> 13078300
A22: 45056 | C22: PC2023/11 | D22: Chi mừng sinh nhật đoàn viên Nguyễn Truyện | F22: 200000 | G22: =+G21+E22-F22 -> 12878300
A23: 45071 | C23: PC2023/12 | D23: Chi mừng sinh nhật đoàn viên Ngô Tiến Đạt | F23: 200000 | G23: =+G22+E23-F23 -> 12678300
... A32: 45285 | C32: PC2023/21 | D32: Chi mừng sinh nhật đoàn viên Nguyễn Thị Thúy Hằng | F32: 200000 | G32: =+G31+E32-F32 -> 7293300
A33: 45291 | C33: PC2023/22 | D33: Chi phụ cấp trách nhiệm Chủ tịch CĐCS (5.010.000 x 0.2) | F33: =5010000*0.2 -> 1002000 | G33: =+G32+E33-F33 -> 6291300
A34: 45291 | C34: PC2023/23 | D34: Chi phụ cấp trách nhiệm Phó Chủ tịch CĐCS (5.010.000 x 0.15) | F34: =5010000*0.15 -> 751500 | G34: =+G33+E34-F34 -> 5539800
A35: 45291 | C35: PC2023/24 | D35: Chi phụ cấp trách nhiệm Kế toán CĐCS (5.010.000 x 0.14) | F35: =5010000*0.14 -> 701400 | G35: =+G34+E35-F35 -> 4838400
A36: 45291 | B36: PT2023/02 | D36: Thu đoàn phí công đoàn 1 % năm 2023 | E36: 6310800 | G36: =+G35+E36-F36 -> 11149200
A38: Cộng | E38: =SUM(E11:E37) -> 13294800 | F38: =SUM(F11:F37) -> 17739900
A39: Số dư cuối kỳ | G39: =+G10+E38-F38 -> 11149200
E41: Ngày 31 tháng 12 năm 2023.
A42: Người ghi sổ | D42: Phụ trách kế toán | E42: Thủ trưởng đơn vị
A43: (Ký, họ tên) | D43: (Ký, họ tên) | E43: (Ký, họ tên, đóng dấu)
D49: NGÔ THỊ BÍCH NGỌC | E49: NGUYỄN THỊ THÚY HĂNG

Sheet SỔ NH 2023
A1: LIÊN ĐOÀN LAO ĐỘNG QUẬN TÂN PHÚ | H1: Mẫu số S12-H
A2: Công đoàn cơ sở: CTY TNHH TKXD & TM Hưng Phát | H2: (Ban hành kèm theo Thông tư số 107/2017/TT-BTC
H3: ngày 10/10/2017 của Bộ Tài chính)
A5: SỔ TIỀN GỬI NGÂN HÀNG
A6: NĂM 2023
A8: Ngày tháng ghi sổ | B8: Chứng từ | D8: DIỄN GIẢI | G8: SỐ TIỀN | J8: Ghi chú
B9: Số hiệu | C9: Ngày tháng | G9: Thu (gửi vào) | H9: Chi (rút ra) | I9: Còn lại
A10: A | B10: B | C10: C | D10: D | G10: 1 | H10: 2 | I10: 3 | J10: F
D11: Số dư đầu kỳ | I11: 26460
C12: 31/01/2023 | D12: Lãi tiền gửi NH | G12: 4 | I12: =+I11+G12-H12 -> 26464
C13: 28/02/2023 | D13: Lãi tiền gửi NH | G13: 4 | I13: =+I12+G13-H13 -> 26468
C14: 31/03/2023 | D14: Lãi tiền gửi NH | G14: 4 | I14: =+I13+G14-H14 -> 26472
C15: 30/04/2023 | D15: Lãi tiền gửi NH | G15: 4 | I15: =+I14+G15-H15 -> 26476
C16: 31/05/2023 | D16: Lãi tiền gửi NH | G16: 4 | I16: =+I15+G16-H16 -> 26480
C17: 30/06/2023 | D17: Lãi tiền gửi NH | G17: 4 | I17: =+I16+G17-H17 -> 26484
C18: 31/07/2023 | D18: Lãi tiền gửi NH | G18: 4 | I18: =+I17+G18-H18 -> 26488
C19: 31/08/2023 | D19: Lãi tiền gửi NH | G19: 4 | I19: =+I18+G19-H19 -> 26492
C20: 30/09/2023 | D20: Lãi tiền gửi NH | G20: 4 | I20: =+I19+G20-H20 -> 26496
C21: 31/10/2023 | D21: Lãi tiền gửi NH | G21: 5 | I21: =+I20+G21-H21 -> 26501
C22: 30/11/2023 | D22: Lãi tiền gửi NH | G22: 4 | I22: =+I21+G22-H22 -> 26505
C23: 31/12/2023 | D23: Lãi tiền gửi NH | G23: 5 | I23: =+I22+G23-H23 -> 26510
F25: Cộng : | G25: =SUM(G12:G24) -> 50
A26: Số dư cuối kỳ | I26: =+I23 -> 26510
H28: Ngày 31 tháng 12 năm 2023
B29: Người ghi sổ | D29: Phụ trách kế toán | H29: Thủ trưởng đơn vị
B30: (Ký, họ tên) | D30: (Ký, họ tên) | H30: (Ký, họ tên, đóng dấu)
D36: NGÔ THỊ BÍCH NGỌC | G36: NGUYỄN THỊ THÚY HẰNG

Sheet BCQT (2024 6 tháng đầu năm)
A1: LIÊN ĐOÀN LAO ĐỘNG QUẬN TÂN PHÚ | E1: Mẫu: B07-TLĐ
A2: Công đoàn cơ sở: CTY TNHH TKXD & TM Hưng Phát | E2: (Ban hành kèm theo hướng dẫn
A3: Địa chỉ: 153G Lũy Bán Bích, P. Tân Thới Hòa, Q. Tân Phú, TP. HCM | E3: số 47 ngày 30/12/2021 của Tổng Liên đoàn)
A4: BÁO CÁO QUYẾT TOÁN THU, CHI TÀI CHÍNH CÔNG ĐOÀN
A5: Từ ngày 01/01/2024 đến 30/06/2024
A6: A- CÁC CHỈ TIÊU CƠ BẢN
A7: - Số lao động Đóng KPCĐ: 10 người | C7: - Quỹ lương đóng KPCĐ: 60,090,000 đồng
A8: - Số đoàn viên: 10 người | C8: - Quỹ lương đóng ĐPCĐ: 60,090,000 đồng
A9: - Số cán bộ CĐ chuyên trách: 3 người
A10: B- CÁC CHỈ TIÊU THU CHI TÀI CHÍNH CÔNG ĐOÀN | F10: Đơn vị tính: đồng
A11: TT | B11: NỘI DUNG | C11: Mục lục TCCĐ (Mã số) | D11: Dự toán được giao | E11: Quyết toán năm | F11: Cấp trên duyệt
A12: I | B12: TÍCH LŨY TÀI CHÍNH ĐẦU KỲ | C12: 10 | E12: 11175710
A13: II | B13: PHẦN THU
A14: 2.1 | B14: Đoàn phí công đoàn | C14: 22 | E14: 3605400
A15: 2.2 | B15: Kinh phí công đoàn | C15: 23
A16: 2.3 | B16: Ngân sách nhà nước cấp hỗ trợ | C16: 24
A17: 2.4 | B17: Các khoản thu khác | C17: 25
B18: - Chuyên môn hỗ trợ | C18: 25.01
B19: - Thu khác | C19: 25.02 | E19: 27
B20: CỘNG THU TÀI CHÍNH CÔNG ĐOÀN | E20: =SUM(E14:E19) -> 3605427
A21: 2.5 | B21: Tài chính công đoàn cấp trên cấp | C21: 28
B22: a- Kinh phí công đoàn cấp trên cấp theo phân phối | C22: 28.01
B23: b- Tài chính công đoàn cấp trên cấp hỗ trợ | C23: 28.02
A24: 2.6 | B24: Nhận bàn giao tài chính | C24: 40
A25: 2.7 | B25: Các khoản khác tăng nguồn tài chính công đoàn | C25: 47
B26: TỔNG CỘNG THU | E26: =SUM(E20:E25) -> 3605427
A27: III | B27: PHẦN CHI
A28: 3.1 | B28: Chi bảo vệ, chăm lo đoàn viên và người lao động | C28: 31 | E28: 9800000
A29: 3.2 | B29: Chi tuyên truyền, đào tạo đoàn viên và người lao động | C29: 32
A30: 3.3 | B30: Chi quản lý hành chính | C30: 33 | E30: 675000
A31: 3.4 | B31: Chi lương, phụ cấp và các khoản phải nộp theo lương | C31: 34
B32: a- Lương, phụ cấp... của cán bộ trong biên chế | C32: 34.01 | E32: 0
B33: b- Phụ cấp cán bộ công đoàn | C33: 34.02
B34: c- Các khoản phải nộp theo lương | C34: 34.03
A35: 3.5 | B35: Chi khác | C35: 37
B36: CỘNG CHI TÀI CHÍNH CÔNG ĐOÀN | E36: =SUM(E28:E35) -> 10475000
A37: 3.6 | B37: ĐPCĐ đã nộp cấp trên quản lý trực tiếp | C37: 39
A38: 3.7 | B38: Bàn giao tài chính công đoàn | C38: 42
A39: 3.8 | B39: Các khoản khác giảm nguồn tài chính công đoàn | C39: 48
B40: TỔNG CỘNG CHI | E40: =+E36+E37 -> 10475000
...

Sheet SỔ TM 2024 6 tháng đầu năm
A1: LIÊN ĐOÀN LAO ĐỘNG QUẬN TÂN PHÚ | F1: Mẫu số S12-H
A2: Công đoàn cơ sở: CTY TNHH TKXD & TM Hưng Phát | F2: (Ban hành kèm theo Thông tư số 107/2017/TT-BTC
F3: ngày 10/10/2017 của Bộ Tài chính)
A4: SỔ QUỸ TIỀN MẶT
A5: Từ ngày 01/01/2024 đến 30/06/2024
A7: SỐ HIỆU CHỨNG TỪ | D7: DIỄN GIẢI | E7: SỐ TIỀN | H7: Ghi chú
A8: Ngày tháng | B8: Thu | C8: Chi | E8: Thu | F8: Chi | G8: Tồn quỹ
A9: A | B9: B | C9: C | D9: E | E9: 1 | F9: 2 | G9: 3 | H9: G
D10: Số dư đầu kỳ | G10: 11149200
A11: 45295 | C11: PC2024/01 | D11: Chi mua bìa đựng hồ sơ | F11: 300000 | G11: =+G10+E11-F11 -> 10849200
A12: 45306 | C12: PC2024/02 | D12: Chi mừng sinh nhật đoàn viên Nguyễn Thị Ngọc Trinh | F12: 200000 | G12: =+G11+E12-F12 -> 10649200
A13: 45313 | C13: PC2024/03 | D13: Chi mua kẹp giấy, kệ xéo nhựa đựng hồ sơ | F13: 375000 | G13: =+G12+E13-F13 -> 10274200
A14: 45324 | C14: PC2024/04 | D14: Chi mừng tết âm lịch cho đoàn viên (10 người) | F14: 5000000 | G14: =+G13+E14-F14 -> 5274200
A15: 45359 | C15: PC2024/05 | D15: Chi mừng lễ 8/3 cho 4 đoàn viên nữ | F15: 800000 | G15: =+G14+E15-F15 -> 4474200
A16: 45365 | C16: PC2024/06 | D16: Chi thăm hỏi ốm đau đoàn viên Ngô Tiến Đạt | F16: 200000 | G16: =+G15+E16-F16 -> 4274200
A17: 45365 | C17: PC2024/07 | D17: Chi thăm hỏi ốm đau đoàn viên Ngô Thị Bích Ngọc | F17: 200000 | G17: =+G16+E17-F17 -> 4074200
A18: 45385 | C18: PC2024/08 | D18: Chi mừng sinh nhật đoàn viên Nguyễn Quốc Đạt | F18: 200000 | G18: =+G17+E18-F18 -> 3874200
A19: 45398 | C19: PC2024/09 | D19: Chi mừng sinh nhật đoàn viên Ngô Thị Bích Ngọc | F19: 200000 | G19: =+G18+E19-F19 -> 3674200
A20: 45399 | C20: PC2024/10 | D20: Chi mừng sinh nhật đoàn viên Nguyễn Bá Quân | F20: 200000 | G20: =+G19+E20-F20 -> 3474200
A21: 45409 | C21: PC2024/11 | D21: Chi mừng lễ 30/4 và 1/5 (10 đoàn viên) | F21: 2000000 | G21: =+G20+E21-F21 -> 1474200
A22: 45417 | C22: PC2024/12 | D22: Chi mừng sinh nhật đoàn viên Nguyễn Kiên Hải | F22: 200000 | G22: =+G21+E22-F22 -> 1274200
... A25: 45472 | C25: PC2024/15 | D25: Chi mừng sinh nhật đoàn viên Lê Văn Điền | F25: 200000 | G25: =+G24+E25-F25 -> 674200
A26: 45473 | B26: PT2024/01 | D26: Thu đoàn phí công đoàn 1 % 6 tháng đầu năm 2024 | E26: 3605400 | G26: =+G25+E26-F26 -> 4279600
A28: Cộng | E28: =SUM(E11:E27) -> 3605400 | F28: =SUM(F11:F27) -> 10475000
A29: Số dư cuối kỳ | G29: =+G10+E28-F28 -> 4279600
E31: Ngày 30 tháng 06 năm 2024.
A32: Người ghi sổ | D32: Phụ trách kế toán | E32: Thủ trưởng đơn vị
A33: (Ký, họ tên) | D33: (Ký, họ tên) | E33: (Ký, họ tên, đóng dấu)
D39: NGÔ THỊ BÍCH NGỌC | E39: NGUYỄN THỊ THÚY HẰNG

Sheet BCQT 2024
A1: LIÊN ĐOÀN LAO ĐỘNG QUẬN TÂN PHÚ | F1: Mẫu: B07-TLĐ
A2: Công đoàn cơ sở: CTY TNHH TKXD & TM Hưng Phát | F2: (Ban hành kèm theo hướng dẫn
A3: Địa chỉ: 153G Lũy Bán Bích, P. Tân Thới Hòa, Q. Tân Phú, TP. HCM | F3: số 47 ngày 30/12/2021 của Tổng Liên đoàn)
A4: BÁO CÁO QUYẾT TOÁN THU, CHI TÀI CHÍNH CÔNG ĐOÀN
A5: Năm 2024
A6: A- CÁC CHỈ TIÊU CƠ BẢN
A7: - Số lao động Đóng KPCĐ: 50 người | C7: - Quỹ lương đóng KPCĐ: | F7: 1378740000 | G7: đồng
A8: - Số đoàn viên: 50 người | C8: - Quỹ lương đóng ĐPCĐ: | F8: 1378740000 | G8: đồng
A9: - Số cán bộ CĐ chuyên trách: 3 người
A10: B- CÁC CHỈ TIÊU THU CHI TÀI CHÍNH CÔNG ĐOÀN | G10: Đơn vị tính: đồng
A11: TT | B11: NỘI DUNG | C11: Mục lục TCCĐ (Mã số) | D11: Dự toán được giao | E11: Quyết toán năm | G11: Cấp trên duyệt
A12: I | B12: TÍCH LŨY TÀI CHÍNH ĐẦU KỲ | C12: 10 | E12: 11175710 | F12: 11175710
A13: II | B13: PHẦN THU
A14: 2.1 | B14: Đoàn phí công đoàn | C14: 22 | E14: 13787400 | F14: 13787400 | I14: =F8*1% -> 13787400
A15: 2.2 | B15: Kinh phí công đoàn | C15: 23
A16: 2.3 | B16: Ngân sách nhà nước cấp hỗ trợ | C16: 24
A17: 2.4 | B17: Các khoản thu khác | C17: 25 | E17: 3364 | F17: 3364
B18: - Chuyên môn hỗ trợ | C18: 25.01
B19: - Thu khác | C19: 25.02 | E19: 3364 | F19: 3364
B20: CỘNG THU TÀI CHÍNH CÔNG ĐOÀN
A21: 2.5 | B21: Tài chính công đoàn cấp trên cấp | C21: 28 | E21: =E22 -> 21902100
B22: a- Kinh phí công đoàn cấp trên cấp theo phân phối | C22: 28.01 | E22: 21902100 | F22: 21902100 | I22: =F7*2%*75% -> 20681100
B23: b- Tài chính công đoàn cấp trên cấp hỗ trợ | C23: 28.02
A24: 2.6 | B24: Nhận bàn giao tài chính | C24: 40
A25: 2.7 | B25: Các khoản khác tăng nguồn tài chính công đoàn | C25: 47
B26: TỔNG CỘNG THU | E26: =E21+E17+E14 -> 35692864
A27: III | B27: PHẦN CHI
A28: 3.1 | B28: Chi bảo vệ, chăm lo đoàn viên và người lao động | C28: 31 | E28: 29000000 | F28: 29000000
A29: 3.2 | B29: Chi tuyên truyền, đào tạo đoàn viên và người lao động | C29: 32
A30: 3.3 | B30: Chi quản lý hành chính | C30: 33 | E30: =1875000+44000+335500 -> 2254500 | F30: 1875000
A31: 3.4 | B31: Chi lương, phụ cấp và các khoản phải nộp theo lương | C31: 34 | E31: =E32+E33+E34 -> 2601900
B32: a- Lương, phụ cấp... của cán bộ trong biên chế | C32: 34.01
B33: b- Phụ cấp cán bộ công đoàn | C33: 34.02 | E33: 2601900 | F33: 2601900
B34: c- Các khoản phải nộp theo lương | C34: 34.03
A35: 3.5 | B35: Chi khác | C35: 37
B36: CỘNG CHI TÀI CHÍNH CÔNG ĐOÀN | E36: =E28+E29+E30+E31+E35 -> 33856400
A37: 3.6 | B37: ĐPCĐ đã nộp cấp trên quản lý trực tiếp | C37: 39 | E37: =3605940+3054600 -> 6660540
A38: 3.7 | B38: Bàn giao tài chính công đoàn | C38: 42
A39: 3.8 | B39: Các khoản khác giảm nguồn tài chính công đoàn | C39: 48
B40: TỔNG CỘNG CHI | E40: =E36+E37 -> 40516940
...

Sheet SỔ TM 2024
A1: LIÊN ĐOÀN LAO ĐỘNG QUẬN TÂN PHÚ | G1: Mẫu số S11H
A2: Công đoàn cơ sở: CTY TNHH TKXD & TM Hưng Phát | G2: (Ban hành kèm theo Thông tư số 107/2017/TT-BTC
G3: ngày 10/10/2017 của Bộ Tài chính)
B4: SỔ QUỸ TIỀN MẶT
B5: NĂM 2024
A7: Ngày tháng ghi sổ | B7: Ngày tháng chứng từ | C7: SỐ HIỆU CHỨNG TỪ | E7: DIỄN GIẢI | F7: SỐ TIỀN | I7: Ghi chú
C8: Thu | D8: Chi | F8: Thu | G8: Chi | H8: Tồn quỹ
A9: A | B9: B | C9: C | D9: D | E9: E | F9: 1 | G9: 2 | H9: 3 | I9: G
E10: Số dư đầu kỳ | H10: 11149200
A11: 45295 | B11: 45295 | D11: PC2024/01 | E11: Chi mua bìa đựng hồ sơ | G11: 300000 | H11: =+H10+F11-G11 -> 10849200
A12: 45306 | B12: 45306 | D12: PC2024/02 | E12: Chi mừng sinh nhật đoàn viên Nguyễn Thị Ngọc Trinh | G12: 200000 | H12: =+H11+F12-G12 -> 10649200
A13: 45313 | B13: 45313 | D13: PC2024/03 | E13: Chi mua kẹp giấy, kệ xéo nhựa đựng hồ sơ | G13: 375000 | H13: =+H12+F13-G13 -> 10274200
A14: 45324 | B14: 45324 | D14: PC2024/04 | E14: Chi mừng tết âm lịch cho đoàn viên (10 người) | G14: 5000000 | H14: =+H13+F14-G14 -> 5274200
A15: 45359 | B15: 45359 | D15: PC2024/05 | E15: Chi mừng lễ 8/3 cho 4 đoàn viên nữ | G15: 800000 | H15: =+H14+F15-G15 -> 4474200
A16: 45365 | B16: 45365 | D16: PC2024/06 | E16: Chi thăm hỏi ốm đau đoàn viên Ngô Tiến Đạt | G16: 200000 | H16: =+H15+F16-G16 -> 4274200
A17: 45365 | B17: 45365 | D17: PC2024/07 | E17: Chi thăm hỏi ốm đau đoàn viên Ngô Thị Bích Ngọc | G17: 200000 | H17: =+H16+F17-G17 -> 4074200
A18: 45385 | B18: 45385 | D18: PC2024/08 | E18: Chi mừng sinh nhật đoàn viên Nguyễn Quốc Đạt | G18: 200000 | H18: =+H17+F18-G18 -> 3874200
A19: 45398 | B19: 45398 | D19: PC2024/09 | E19: Chi mừng sinh nhật đoàn viên Ngô Thị Bích Ngọc | G19: 200000 | H19: =+H18+F19-G19 -> 3674200
A20: 45399 | B20: 45399 | D20: PC2024/10 | E20: Chi mừng sinh nhật đoàn viên Nguyễn Bá Quân | G20: 200000 | H20: =+H19+F20-G20 -> 3474200
A21: 45409 | B21: 45409 | D21: PC2024/11 | E21: Chi mừng lễ 30/4 và 1/5 (10 đoàn viên) | G21: 2000000 | H21: =+H20+F21-G21 -> 1474200
A22: 45417 | B22: 45417 | D22: PC2024/12 | E22: Chi mừng sinh nhật đoàn viên Nguyễn Kiên Hải | G22: 200000 | H22: =+H21+F22-G22 -> 1274200
... A25: 45472 | B25: 45472 | D25: PC2024/15 | E25: Chi mừng sinh nhật đoàn viên Lê Văn Điền | G25: 200000 | H25: =+H24+F25-G25 -> 674200
A26: 45473 | B26: 45473 | C26: PT2024/01 | E26: Thu đoàn phí công đoàn 1% 6 tháng đầu năm 2024 | F26: 3605400 | H26: =+H25+F26-G26 -> 4279600
A27: 45504 | B27: 45504 | D27: PC2024/16 | E27: Chi mừng đoàn viên Nguyễn Thị Thúy Hằng sinh con | G27: 500000 | H27: =+H26+F27-G27 -> 3779600
A28: 45512 | B28: 45512 | D28: PC2024/17 | E28: Chi mua văn phòng phẩm | G28: 510000 | H28: =+H27+F28-G28 -> 3269600
A29: 45523 | B29: 45523 | D29: PC2024/18 | E29: Chi thăm hỏi ốm đau con đoàn viên Ngô Tiến Đạt | G29: 200000 | H29: =+H28+F29-G29 -> 3069600
A30: 45535 | B30: 45535 | D30: PC2024/19 | E30: Chi mừng Lễ 02/09 (10 đoàn viên) | G30: 2000000 | H30: =+H29+F30-G30 -> 1069600
A31: 45548 | B31: 45548 | D31: PC2024/20 | E31: Chi mừng Tết Trung Thu cho con Đoàn viên (7 bé) | G31: 700000 | H31: =+H30+F31-G31 -> 369600
A32: 45555 | B32: 45555 | C32: PT2024/02 | E32: Rút tiền gửi ngân hàng nhập quỹ tiền mặt | F32: 6000000 | H32: =H31+F32-G32 -> 6369600
A33: 45555 | B33: 45555 | D33: PC2024/21 | E33: Chi nộp cấp quản lý trực tiếp 40% ĐPCĐ 1% năm 2023 | G33: 2524320 | H33: =H32+F33-G33 -> 3845280
A34: 45555 | B34: 45555 | D34: PC2024/22 | E34: Phí ngân hàng _chi nộp cấp quản lý trực tiếp 40% ĐPCĐ 1% năm 2023 | G34: 22000 | H34: =H33+F34-G34 -> 3823280
A35: 45555 | B35: 45555 | D35: PC2024/23 | E35: Chi nộp cấp quản lý trực tiếp 30% ĐPCĐ 1% Quý 1, 2 năm 2024 | G35: 1081620 | H35: =H34+F35-G35 -> 2741660
A36: 45555 | B36: 45555 | D36: PC2024/24 | E36: Phí ngân hàng_chi nộp cấp quản lý trực tiếp 30% ĐPCĐ 1% Quý 1, 2 năm 2024 | G36: 22000 | H36: =H35+F36-G36 -> 2719660
A37: 45555 | B37: 45555 | D37: PC2024/25 | E37: Chi mừng sinh nhật đoàn viên Nguyễn Thị Cẩm Ly | G37: 200000 | H37: =H36+F37-G37 -> 2519660
A38: 45565 | B38: 45565 | C38: PT2024/03 | E38: Thu đoàn phí công đoàn 1% Quý 3 năm 2024 | F38: 1883700 | H38: =H37+F38-G38 -> 4403360
A39: 45576 | B39: 45576 | D39: PC2024/26 | E39: Chi mừng sinh nhật đoàn viên Vòng Và Tuấn | G39: 200000 | H39: =H38+F39-G39 -> 4203360
A40: 45580 | B40: 45580 | D40: PC2024/27 | E40: Chi mừng sinh nhật đoàn viên Ngô Thị Tuyết | G40: 200000 | H40: =H39+F40-G40 -> 4003360
A41: 45581 | B41: 45581 | C41: PT2024/04 | E41: Rút tiền gửi ngân hàng nhập quỹ tiền mặt | F41: 8500000 | H41: =H40+F41-G41 -> 12503360
A42: 45585 | B42: 45585 | D42: PC2024/28 | E42: Chi mừng lễ 20/10 cho 19 đoàn viên nữ | G42: 3800000 | H42: =H41+F42-G42 -> 8703360
A43: 45594 | B43: 45594 | D43: PC2024/29 | E43: Chi mừng sinh nhật đoàn viên Lê Thị Nhã Mi | G43: 200000 | H43: =H42+F43-G43 -> 8503360
...

Sheet SỔ NH 2024
A1: LIÊN ĐOÀN LAO ĐỘNG QUẬN TÂN PHÚ | H1: Mẫu số S12-H
A2: Công đoàn cơ sở: CTY TNHH TKXD & TM Hưng Phát | H2: (Ban hành kèm theo Thông tư số 107/2017/TT-BTC
H3: ngày 10/10/2017 của Bộ Tài chính)
A5: SỔ TIỀN GỬI NGÂN HÀNG
A6: Từ ngày 01/01/2024 đến ngày 31/12/2024
D7: Nơi mở tài khoản giao dịch:................
D8: Số hiệu tài khoản tại nơi gửi:..............
D9: Loại tiền gửi:.......................................
A11: Ngày tháng ghi sổ | B11: Chứng từ | D11: DIỄN GIẢI | G11: SỐ TIỀN | J11: Ghi chú
B12: Số hiệu | C12: Ngày tháng | G12: Thu (gửi vào) | H12: Chi (rút ra) | I12: Còn lại
A13: A | B13: B | C13: C | D13: D | G13: 1 | H13: 2 | I13: 3 | J13: E
D14: Số dư đầu kỳ | I14: 26510
A15: 45322 | B15: BC-01 | C15: 45322 | D15: Lãi tiền gửi NH | G15: 5 | I15: =+I14+G15-H15 -> 26515
A16: 45350 | B16: BC-02 | C16: 45350 | D16: Lãi tiền gửi NH | G16: 4 | I16: =+I15+G16-H16 -> 26519
A17: 45382 | B17: BC-03 | C17: 45382 | D17: Lãi tiền gửi NH | G17: 5 | I17: =+I16+G17-H17 -> 26524
A18: 45412 | B18: BC-04 | C18: 45412 | D18: Lãi tiền gửi NH | G18: 4 | I18: =+I17+G18-H18 -> 26528
A19: 45443 | B19: BC-05 | C19: 45443 | D19: Lãi tiền gửi NH | G19: 5 | I19: =+I18+G19-H19 -> 26533
A20: 45473 | B20: BC-06 | C20: 45473 | D20: Lãi tiền gửi NH | G20: 4 | I20: =+I19+G20-H20 -> 26537
A21: 45504 | B21: BC-07 | C21: 45504 | D21: Lãi tiền gửi NH | G21: 5 | I21: =+I20+G21-H21 -> 26542 | K21: 2023 | L21: 2024
A22: 45534 | B22: BC-08 | C22: 45534 | D22: Nhận 75% KPCĐ Cấp trên của năm 2023 và 6 tháng đầu năm 2024 | G22: 14874300 | I22: =+I21+G22-H22 -> 14900842
A23: 45535 | B23: BC-09 | C23: 45535 | D23: Lãi tiền gửi NH | G23: 86 | I23: =+I22+G23-H23 -> 14900928
A24: 45555 | B24: PT2024/02 | C24: 45555 | D24: Rút tiền gửi ngân hàng nhập quỹ tiền mặt | H24: 6000000 | I24: =+I23+G24-H24 -> 8900928
A25: 45565 | B25: BC-10 | C25: 45565 | D25: Lãi tiền gửi NH | G25: 2121 | I25: =+I24+G25-H25 -> 8903049
A26: 45581 | B26: PT2024/04 | C26: 45581 | D26: Rút tiền gửi ngân hàng nhập quỹ tiền mặt | H26: 8500000 | I26: =+I25+G26-H26 -> 403049
A27: 45581 | B27: UNC-1 | C27: 45581 | D27: Chi tiền phí dịch vụ E-Fast | H27: 220000 | I27: =+I26+G27-H27 -> 183049
A28: 45582 | B28: UNC-2 | C28: 45582 | D28: Thu phí dịch vụ IB Tháng 10/2024 | H28: 35000 | I28: =+I27+G28-H28 -> 148049
A29: 45582 | B29: UNC-3 | C29: 45582 | D29: VAT phí dịch vụ IB Tháng 10/2024 | H29: 3500 | I29: =+I28+G29-H29 -> 144549
A30: 45596 | B30: BC-11 | C30: 45596 | D30: Lãi tiền gửi NH | G30: 793 | I30: =+I29+G30-H30 -> 145342
A31: 45613 | B31: UNC-4 | C31: 45613 | D31: Thu phí dịch vụ IB Tháng 11/2024 | H31: 35000 | I31: =+I30+G31-H31 -> 110342
A32: 45613 | B32: UNC-5 | C32: 45613 | D32: VAT phí dịch vụ IB Tháng 11/2024 | H32: 3500 | I32: =+I31+G32-H32 -> 106842
A33: 45625 | B33: BC-12 | C33: 45625 | D33: Nhận 75% KPCĐ Cấp trên của quý 3 năm 2024 | G33: 2825550 | I33: =+I32+G33-H33 -> 2932392
A34: 45626 | B34: BC-13 | C34: 45626 | D34: Lãi tiền gửi NH | G34: 37 | I34: =+I33+G34-H34 -> 2932429
A35: 45628 | B35: UNC-6 | C35: 45628 | D35: Nộp 30% ĐPCĐ Quý 3 năm 2024 | H35: 565110 | I35: =+I34+G35-H35 -> 2367319
A36: 45628 | B36: UNC-7 | C36: 45628 | D36: Nộp 30% ĐPCĐ Tháng 10 năm 2024 | H36: 840450 | I36: =+I35+G36-H36 -> 1526869
A37: 45643 | B37: UNC-8 | C37: 45643 | D37: Thu phí dịch vụ IB Tháng 12/2024 | H37: 35000 | I37: =+I36+G37-H37 -> 1491869
A38: 45643 | B38: UNC-9 | C38: 45643 | D38: VAT phí dịch vụ IB Tháng 12/2024 | H38: 3500 | I38: =+I37+G38-H38 -> 1488369
A39: 45656 | B39: BC-14 | C39: 45656 | D39: Nhận 75% KPCĐ Cấp trên của tháng 10 năm 2024 | G39: 4202250 | I39: =+I38+G39-H39 -> 5690619
A40: 45657 | B40: BC-15 | C40: 45657 | D40: Lãi tiền gửi NH | G40: 295 | I40: =+I39+G40-H40 -> 5690914
A41: 45657 | B41: UNC-10 | C41: 45657 | D41: Nộp 30% ĐPCĐ Tháng 11 năm 2024 | H41: 824520 | I41: =+I40+G41-H41 -> 4866394
A42: 45657 | B42: UNC-11 | C42: 45657 | D42: Nộp 30% ĐPCĐ Tháng 12 năm 2024 | H42: 824520 | I42: =+I41+G42-H42 -> 4041874
...

Sheet BANG KIEM KE TIEN MAT 2024
A2: Liên Đoàn Lao Động Quận Tân Phú | D2: Mẫu số C34-HD
A3: CĐCS: Công Ty TNHH TK XD & TM Hưng Phát
A5: BIÊN BẢN KIỂM KÊ QUỸ TIỀN MẶT
A7: Hôm nay, ngày 31 tháng 12 năm 2024, vào hồi 15 giờ 30 phút.
A9: Ban kiểm kê bao gồm:
A10: Ông/Bà: Ngô Thị Bích Ngọc | C10: Chủ tịch CĐCS Trưởng Ban
A11: Ông/Bà: Nguyễn Thị Cẩm Ly | C11: Kế toán Ủy viên
A13: STT | B13: Diễn giải | C13: Số lượng (tờ) | D13: Số tiền | E13: KẾ TOÁN VÀ THỦ QUỸ PHẢI KIỂM VỚI NHAU TRÁCH SAI SÓT TIỀN
A14: A | B14: B | C14: 1 | D14: 2
A15: I | B15: Số dư theo số quỹ | D15: 2309760 | E15: ghi theo số cuối kỳ sổ tiền mặt của báo cáo quyết toán
A16: II | B16: Số kiểm kê thực tế | D16: 2310000 | E16: Ghi theo số kiểm kê tiền mặt tại quỹ do thủ quỹ giữ
A17: 1 | B17: - Loại 500.000đ | C17: 2 | D17: 1000000
A18: 2 | B18: - Loại 200.000đ | C18: 5 | D18: 1000000
A19: 3 | B19: - Loại 100.000đ | C19: 3 | D19: 300000
A20: 4 | B20: - Loại 50.000đ
A21: 5 | B21: - Loại 20.000đ
A22: 6 | B22: - Loại 10.000đ | C22: 1 | D22: 10000
A23: 7 | B23: - Loại 5.000đ
A24: 8 | B24: - Loại 2.000đ
A25: 9 | B25: - Loại 1.000đ
A26: 10 | B26: - Loại 500đ
A27: 7 | B27: - … | E27: lưu ý trên lệch không quá 500đ
A28: III | B28: Chênh lệch: | D28: =D16-D15 -> 240
A29: - Lý do: | B29: + Dư: 240đ
A30: - Kết luận sau khi kiểm quỹ: Dư 240đ do số lẻ.
B32: Kế toán | C32: Thủ quỹ | D32: Người chịu trách nhiệm kiểm kê quỹ
B33: (Ký, họ tên) | C33: (Ký, họ tên) | D33: (Ký, họ tên)
B38: Nguyễn Thị Cẩm Ly | D38: Ngô Thị Bích Ngọc

Sheet BCQT 2025 (01.01-31.05)
A1: LIÊN ĐOÀN LAO ĐỘNG QUẬN TÂN PHÚ | F1: Mẫu: B07-TLĐ
A2: Công đoàn cơ sở: CTY TNHH TKXD & TM Hưng Phát | F2: (Ban hành kèm theo hướng dẫn
A3: Địa chỉ: 153G Lũy Bán Bích, P. Tân Thới Hòa, Q. Tân Phú, TP. HCM | F3: số 47 ngày 30/12/2021 của Tổng Liên đoàn)
A4: BÁO CÁO QUYẾT TOÁN THU, CHI TÀI CHÍNH CÔNG ĐOÀN
A5: Từ ngày 01/01/2025 đến 31/05/2025
A6: A- CÁC CHỈ TIÊU CƠ BẢN
A7: - Số lao động Đóng KPCĐ: 47 người | C7: - Quỹ lương đóng KPCĐ: | F7: 1315790000 | G7: đồng | I7: =+F7/6 -> 2.1929833e+08
A8: - Số đoàn viên: 47 người | C8: - Quỹ lương đóng ĐPCĐ: | F8: 1315790000 | G8: đồng | I8: =+I7/47 -> 4665922
A9: - Số cán bộ CĐ chuyên trách: 3 người | I9: =+I8/100 -> 46659.22
A10: B- CÁC CHỈ TIÊU THU CHI TÀI CHÍNH CÔNG ĐOÀN | G10: Đơn vị tính: đồng
A11: TT | B11: NỘI DUNG | C11: Mục lục TCCĐ (Mã số) | D11: Dự toán được giao | E11: Quyết toán năm | G11: Cấp trên duyệt
A12: I | B12: TÍCH LŨY TÀI CHÍNH ĐẦU KỲ | C12: 10 | E12: 6351634
A13: II | B13: PHẦN THU
A14: 2.1 | B14: Đoàn phí công đoàn | C14: 22 | E14: 15747000 | F14: 13787400 | I14: =F8*1% -> 13157900
A15: 2.2 | B15: Kinh phí công đoàn | C15: 23
A16: 2.3 | B16: Ngân sách nhà nước cấp hỗ trợ | C16: 24
A17: 2.4 | B17: Các khoản thu khác | C17: 25 | E17: 1440 | F17: 3364
B18: - Chuyên môn hỗ trợ | C18: 25.01
B19: - Thu khác | C19: 25.02 | E19: 1440 | F19: 3364
B20: CỘNG THU TÀI CHÍNH CÔNG ĐOÀN
A21: 2.5 | B21: Tài chính công đoàn cấp trên cấp | C21: 28 | E21: =E22 -> 20214750
B22: a- Kinh phí công đoàn cấp trên cấp theo phân phối | C22: 28.01 | E22: 20214750 | F22: 21902100 | I22: =F7*2%*75% -> 19736850
B23: b- Tài chính công đoàn cấp trên cấp hỗ trợ | C23: 28.02
A24: 2.6 | B24: Nhận bàn giao tài chính | C24: 40
A25: 2.7 | B25: Các khoản khác tăng nguồn tài chính công đoàn | C25: 47
B26: TỔNG CỘNG THU | E26: =E21+E17+E14 -> 35963190
A27: III | B27: PHẦN CHI
A28: 3.1 | B28: Chi bảo vệ, chăm lo đoàn viên và người lao động | C28: 31 | E28: 34900000 | F28: 29000000
A29: 3.2 | B29: Chi tuyên truyền, đào tạo đoàn viên và người lao động | C29: 32
A30: 3.3 | B30: Chi quản lý hành chính | C30: 33 | E30: 800000 | F30: 1875000
A31: 3.4 | B31: Chi lương, phụ cấp và các khoản phải nộp theo lương | C31: 34
B32: a- Lương, phụ cấp... của cán bộ trong biên chế | C32: 34.01
B33: b- Phụ cấp cán bộ công đoàn | C33: 34.02
B34: c- Các khoản phải nộp theo lương | C34: 34.03
A35: 3.5 | B35: Chi khác | C35: 37 | E35: 192500 | F35: 192500 | I35: =+E30+E35 -> 992500
B36: CỘNG CHI TÀI CHÍNH CÔNG ĐOÀN | E36: =E28+E29+E30+E31+E35 -> 35892500
A37: 3.6 | B37: ĐPCĐ đã nộp cấp trên quản lý trực tiếp | C37: 39 | E37: 2393910 | F37: 3170640
A38: 3.7 | B38: Bàn giao tài chính công đoàn | C38: 42
A39: 3.8 | B39: Các khoản khác giảm nguồn tài chính công đoàn | C39: 48
B40: TỔNG CỘNG CHI | E40: =E36+E37 -> 38286410 | I40: 56760
...

Sheet BCQT 2025 (01.06-13.06) 
A1: LIÊN ĐOÀN LAO ĐỘNG QUẬN TÂN PHÚ | F1: Mẫu: B07-TLĐ
A2: Công đoàn cơ sở: CTY TNHH TKXD & TM Hưng Phát | F2: (Ban hành kèm theo hướng dẫn
A3: Địa chỉ: 153G Lũy Bán Bích, P. Tân Thới Hòa, Q. Tân Phú, TP. HCM | F3: số 47 ngày 30/12/2021 của Tổng Liên đoàn)
A4: BÁO CÁO QUYẾT TOÁN THU, CHI TÀI CHÍNH CÔNG ĐOÀN
A5: Từ ngày 01/06/2025 đến 13/06/2025
A6: A- CÁC CHỈ TIÊU CƠ BẢN
A7: - Số lao động Đóng KPCĐ: 48 người | C7: - Quỹ lương đóng KPCĐ: | F7: 264220000 | G7: đồng
A8: - Số đoàn viên: 48 người | C8: - Quỹ lương đóng ĐPCĐ: | F8: 264220000 | G8: đồng
A9: - Số cán bộ CĐ chuyên trách: 3 người
A10: B- CÁC CHỈ TIÊU THU CHI TÀI CHÍNH CÔNG ĐOÀN | G10: Đơn vị tính: đồng
A11: TT | B11: NỘI DUNG | C11: Mục lục TCCĐ (Mã số) | D11: Dự toán được giao | E11: Quyết toán năm | G11: Cấp trên duyệt
A12: I | B12: TÍCH LŨY TÀI CHÍNH ĐẦU KỲ | C12: 10 | E12: 4028414
A13: II | B13: PHẦN THU
A14: 2.1 | B14: Đoàn phí công đoàn | C14: 22 | E14: 53100 | F14: 13787400 | I14: =F8*1% -> 2642200
A15: 2.2 | B15: Kinh phí công đoàn | C15: 23
A16: 2.3 | B16: Ngân sách nhà nước cấp hỗ trợ | C16: 24
A17: 2.4 | B17: Các khoản thu khác | C17: 25 | E17: =E19 -> 0 | F17: 3364
B18: - Chuyên môn hỗ trợ | C18: 25.01
B19: - Thu khác | C19: 25.02
B20: CỘNG THU TÀI CHÍNH CÔNG ĐOÀN
A21: 2.5 | B21: Tài chính công đoàn cấp trên cấp | C21: 28 | E21: =E22 -> 0
B22: a- Kinh phí công đoàn cấp trên cấp theo phân phối | C22: 28.01 | I22: =F7*2%*75% -> 3963300
B23: b- Tài chính công đoàn cấp trên cấp hỗ trợ | C23: 28.02
A24: 2.6 | B24: Nhận bàn giao tài chính | C24: 40
A25: 2.7 | B25: Các khoản khác tăng nguồn tài chính công đoàn | C25: 47
B26: TỔNG CỘNG THU | E26: =E21+E17+E14 -> 53100
A27: III | B27: PHẦN CHI
A28: 3.1 | B28: Chi bảo vệ, chăm lo đoàn viên và người lao động | C28: 31 | E28: 1800000 | F28: 29000000
A29: 3.2 | B29: Chi tuyên truyền, đào tạo đoàn viên và người lao động | C29: 32
A30: 3.3 | B30: Chi quản lý hành chính | C30: 33
A31: 3.4 | B31: Chi lương, phụ cấp và các khoản phải nộp theo lương | C31: 34
B32: a- Lương, phụ cấp... của cán bộ trong biên chế | C32: 34.01
B33: b- Phụ cấp cán bộ công đoàn | C33: 34.02
B34: c- Các khoản phải nộp theo lương | C34: 34.03
A35: 3.5 | B35: Chi khác | C35: 37
B36: CỘNG CHI TÀI CHÍNH CÔNG ĐOÀN | E36: =E28+E29+E30+E31+E35 -> 1800000
A37: 3.6 | B37: ĐPCĐ đã nộp cấp trên quản lý trực tiếp | C37: 39 | E37: 776730 | F37: 3170640
A38: 3.7 | B38: Bàn giao tài chính công đoàn | C38: 42
A39: 3.8 | B39: Các khoản khác giảm nguồn tài chính công đoàn | C39: 48
B40: TỔNG CỘNG CHI | E40: =E36+E37 -> 2576730 | I40: 1309860 | J40: TM
...

Sheet BCQT 2025 (14.06-31.12)
A1: LIÊN ĐOÀN LAO ĐỘNG TP HỒ CHÍ MINH | F1: Mẫu: B07-TLĐ
A2: Công đoàn cơ sở: CTY TNHH TKXD & TM Hưng Phát | F2: (Ban hành kèm theo hướng dẫn
A3: Địa chỉ: 153G Lũy Bán Bích, Phường Phú Thạnh, TP. HCM | F3: số 47 ngày 30/12/2021 của Tổng Liên đoàn)
A4: BÁO CÁO QUYẾT TOÁN THU, CHI TÀI CHÍNH CÔNG ĐOÀN
A5: Từ ngày 14/06/2025 đến 31/12/2025
A6: A- CÁC CHỈ TIÊU CƠ BẢN
A7: - Số lao động Đóng KPCĐ: 42 người | C7: - Quỹ lương đóng KPCĐ: | F7: 227050000 | G7: đồng
A8: - Số đoàn viên: 42 người | C8: - Quỹ lương đóng ĐPCĐ: | F8: 227050000 | G8: đồng
A9: - Số cán bộ CĐ chuyên trách: 3 người
A10: B- CÁC CHỈ TIÊU THU CHI TÀI CHÍNH CÔNG ĐOÀN | G10: Đơn vị tính: đồng
A11: TT | B11: NỘI DUNG | C11: Mục lục TCCĐ (Mã số) | D11: Dự toán được giao | E11: Quyết toán năm | G11: Cấp trên duyệt
A12: I | B12: TÍCH LŨY TÀI CHÍNH ĐẦU KỲ | C12: 10 | E12: 1504784
A13: II | B13: PHẦN THU
A14: 2.1 | B14: Đoàn phí công đoàn | C14: 22 | E14: =+'SỔ TM 2025'!F57+'SỔ TM 2025'!F59+'SỔ TM 2025'!F69+'SỔ TM 2025'!F71+'SỔ TM 2025'!F73+'SỔ TM 2025'!F78 -> 7422150 | F14: 13787400
A15: 2.2 | B15: Kinh phí công đoàn | C15: 23
A16: 2.3 | B16: Ngân sách nhà nước cấp hỗ trợ | C16: 24
A17: 2.4 | B17: Các khoản thu khác | C17: 25 | E17: =E19 -> 223396 | F17: 3364
B18: - Chuyên môn hỗ trợ | C18: 25.01
B19: - Thu khác | C19: 25.02 | E19: 223396
B20: CỘNG THU TÀI CHÍNH CÔNG ĐOÀN
A21: 2.5 | B21: Tài chính công đoàn cấp trên cấp | C21: 28 | E21: =E22 -> 7767000
B22: a- Kinh phí công đoàn cấp trên cấp theo phân phối | C22: 28.01 | E22: =+'SỔ NH 2025 '!G53 -> 7767000
B23: b- Tài chính công đoàn cấp trên cấp hỗ trợ | C23: 28.02
A24: 2.6 | B24: Nhận bàn giao tài chính | C24: 40
A25: 2.7 | B25: Các khoản khác tăng nguồn tài chính công đoàn | C25: 47
B26: TỔNG CỘNG THU | E26: =E21+E17+E14 -> 15412546
A27: III | B27: PHẦN CHI
A28: 3.1 | B28: Chi bảo vệ, chăm lo đoàn viên và người lao động | C28: 31 | E28: =+SUM('SỔ TM 2025'!G51:G82)-'BCQT 2025 (14.06-31.12)'!E30:F30 -> 13761000
A29: 3.2 | B29: Chi tuyên truyền, đào tạo đoàn viên và người lao động | C29: 32
A30: 3.3 | B30: Chi quản lý hành chính | C30: 33 | E30: =+'SỔ TM 2025'!G61 -> 756000
A31: 3.4 | B31: Chi lương, phụ cấp và các khoản phải nộp theo lương | C31: 34
B32: a- Lương, phụ cấp... của cán bộ trong biên chế | C32: 34.01
B33: b- Phụ cấp cán bộ công đoàn | C33: 34.02
B34: c- Các khoản phải nộp theo lương | C34: 34.03
A35: 3.5 | B35: Chi khác | C35: 37 | E35: 269500
B36: CỘNG CHI TÀI CHÍNH CÔNG ĐOÀN | E36: =E28+E29+E30+E31+E35 -> 14786500
A37: 3.6 | B37: ĐPCĐ đã nộp cấp trên quản lý trực tiếp | C37: 39 | E37: =+'SỔ NH 2025 '!H54+'SỔ NH 2025 '!H55 -> 1569390 | F37: 3170640
A38: 3.7 | B38: Bàn giao tài chính công đoàn | C38: 42
A39: 3.8 | B39: Các khoản khác giảm nguồn tài chính công đoàn | C39: 48
B40: TỔNG CỘNG CHI | E40: =E36+E37 -> 16355890 | I40: =+'SỔ TM 2025'!H84 -> 438010 | J40: TM
...

Sheet SỔ TM 2025
A1: LIÊN ĐOÀN LAO ĐỘNG TP HỒ CHÍ MINH | G1: Mẫu số S11H
A2: Công đoàn cơ sở: CTY TNHH TKXD & TM Hưng Phát | G2: (Ban hành kèm theo Thông tư số 107/2017/TT-BTC
G3: ngày 10/10/2017 của Bộ Tài chính)
B4: SỔ QUỸ TIỀN MẶT | J4: 1452000
B5: NĂM 2025
A7: Ngày tháng ghi sổ | B7: Ngày tháng chứng từ | C7: SỐ HIỆU CHỨNG TỪ | E7: DIỄN GIẢI | F7: SỐ TIỀN | I7: Ghi chú
C8: Thu | D8: Chi | F8: Thu | G8: Chi | H8: Tồn quỹ
A9: A | B9: B | C9: C | D9: D | E9: E | F9: 1 | G9: 2 | H9: 3 | I9: G
E10: Số dư đầu kỳ | H10: 2309760
A11: 45659 | B11: 45659 | C11: =IF(AND(LEFT(E11,3)<>"Chi",E11<>""),"PT2025/"&TEXT(COUNTIF($E11:E$11,"<>Chi*"),"00"),"") | D11: =IF(AND(LEFT(E11,3)="Chi",E11<>""),"PC2025/"&TEXT(COUNTIF($E11:E$11,"Chi*"),"00"),"") -> PC2025/01 | E11: Chi mừng sinh nhật đoàn viên Trần Hải Đăng (01/01) | G11: 300000 | H11: =+H10+F11-G11 -> 2009760 | J11: x
A12: 45659 | B12: 45659 | C12: =IF(AND(LEFT(E12,3)<>"Chi",E12<>""),"PT2025/"&TEXT(COUNTIF($E$11:E12,"<>Chi*"),"00"),"") | D12: =IF(AND(LEFT(E12,3)="Chi",E12<>""),"PC2025/"&TEXT(COUNTIF($E$11:E12,"Chi*"),"00"),"") -> PC2025/02 | E12: Chi mừng sinh nhật đoàn viên Phùng Kim Ngân | G12: 300000 | H12: =+H11+F12-G12 -> 1709760
A13: 45672 | B13: 45672 | C13: =IF(AND(LEFT(E13,3)<>"Chi",E13<>""),"PT2025/"&TEXT(COUNTIF($E$11:E13,"<>Chi*"),"00"),"") | D13: =IF(AND(LEFT(E13,3)="Chi",E13<>""),"PC2025/"&TEXT(COUNTIF($E$11:E13,"Chi*"),"00"),"") -> PC2025/03 | E13: Chi mừng sinh nhật đoàn viên Nguyễn Thị Ngọc Trinh | G13: 300000 | H13: =+H12+F13-G13 -> 1409760 | K13: ok
A14: 45691 | B14: 45691 | C14: =IF(AND(LEFT(E14,3)<>"Chi",E14<>""),"PT2025/"&TEXT(COUNTIF($E$11:E14,"<>Chi*"),"00"),"") | D14: =IF(AND(LEFT(E14,3)="Chi",E14<>""),"PC2025/"&TEXT(COUNTIF($E$11:E14,"Chi*"),"00"),"") -> PC2025/04 | E14: Chi mừng sinh nhật đoàn viên Nguyễn Thanh Phong (29/01) | G14: 300000 | H14: =+H13+F14-G14 -> 1109760 | J14: x
A15: 45691 | B15: 45691 | C15: =IF(AND(LEFT(E15,3)<>"Chi",E15<>""),"PT2025/"&TEXT(COUNTIF($E$11:E15,"<>Chi*"),"00"),"") | D15: =IF(AND(LEFT(E15,3)="Chi",E15<>""),"PC2025/"&TEXT(COUNTIF($E$11:E15,"Chi*"),"00"),"") -> PC2025/05 | E15: Chi mừng sinh nhật đoàn viên Nguyễn Thị Kỳ Duyên (31/01) | G15: 300000 | H15: =+H14+F15-G15 -> 809760 | J15: x
A16: 45691 | B16: 45691 | C16: =IF(AND(LEFT(E16,3)<>"Chi",E16<>""),"PT2025/"&TEXT(COUNTIF($E$11:E16,"<>Chi*"),"00"),"") | D16: =IF(AND(LEFT(E16,3)="Chi",E16<>""),"PC2025/"&TEXT(COUNTIF($E$11:E16,"Chi*"),"00"),"") -> PC2025/06 | E16: Chi mừng sinh nhật đoàn viên Võ Thanh Lam (01/02) | G16: 300000 | H16: =+H15+F16-G16 -> 509760 | J16: x
A17: 45691 | B17: 45691 | C17: =IF(AND(LEFT(E17,3)<>"Chi",E17<>""),"PT2025/"&TEXT(COUNTIF($E$11:E17,"<>Chi*"),"00"),"") -> PT2025/01 | D17: =IF(AND(LEFT(E17,3)="Chi",E17<>""),"PC2025/"&TEXT(COUNTIF($E$11:E17,"Chi*"),"00"),"") | E17: Thu đoàn phí công đoàn 1% quý 1 năm 2025 | F17: 7979700 | H17: =+H16+F17-G17 -> 8489460 | J17: x
A18: 45691 | B18: 45691 | C18: =IF(AND(LEFT(E18,3)<>"Chi",E18<>""),"PT2025/"&TEXT(COUNTIF($E$11:E18,"<>Chi*"),"00"),"") -> PT2025/02 | D18: =IF(AND(LEFT(E18,3)="Chi",E18<>""),"PC2025/"&TEXT(COUNTIF($E$11:E18,"Chi*"),"00"),"") | E18: Rút tiền gửi ngân hàng nhập quỹ tiền mặt | F18: 8000000 | H18: =+H17+F18-G18 -> 16489460
A19: 45691 | B19: 45691 | C19: =IF(AND(LEFT(E19,3)<>"Chi",E19<>""),"PT2025/"&TEXT(COUNTIF($E$11:E19,"<>Chi*"),"00"),"") | D19: =IF(AND(LEFT(E19,3)="Chi",E19<>""),"PC2025/"&TEXT(COUNTIF($E$11:E19,"Chi*"),"00"),"") -> PC2025/07 | E19: Chi mừng tết âm lịch cho đoàn viên (50 người) | G19: =300000*50 -> 15000000 | H19: =+H18+F19-G19 -> 1489460
A20: 45693 | B20: 45693 | C20: =IF(AND(LEFT(E20,3)<>"Chi",E20<>""),"PT2025/"&TEXT(COUNTIF($E$11:E20,"<>Chi*"),"00"),"") | D20: =IF(AND(LEFT(E20,3)="Chi",E20<>""),"PC2025/"&TEXT(COUNTIF($E$11:E20,"Chi*"),"00"),"") -> PC2025/08 | E20: Chi mừng sinh nhật đoàn viên Võ Thành Hưng | G20: 300000 | H20: =+H19+F20-G20 -> 1189460
A21: 45700 | B21: 45700 | C21: =IF(AND(LEFT(E21,3)<>"Chi",E21<>""),"PT2025/"&TEXT(COUNTIF($E$11:E21,"<>Chi*"),"00"),"") | D21: =IF(AND(LEFT(E21,3)="Chi",E21<>""),"PC2025/"&TEXT(COUNTIF($E$11:E21,"Chi*"),"00"),"") -> PC2025/09 | E21: Chi mừng sinh nhật đoàn viên Bùi Xuân Mai Thảo | G21: 300000 | H21: =+H20+F21-G21 -> 889460
A22: 45708 | B22: 45708 | C22: =IF(AND(LEFT(E22,3)<>"Chi",E22<>""),"PT2025/"&TEXT(COUNTIF($E$11:E22,"<>Chi*"),"00"),"") | D22: =IF(AND(LEFT(E22,3)="Chi",E22<>""),"PC2025/"&TEXT(COUNTIF($E$11:E22,"Chi*"),"00"),"") -> PC2025/10 | E22: Chi mừng sinh nhật đoàn viên Huỳnh Thế Sơn | G22: 300000 | H22: =+H21+F22-G22 -> 589460
A23: 45710 | B23: 45710 | C23: =IF(AND(LEFT(E23,3)<>"Chi",E23<>""),"PT2025/"&TEXT(COUNTIF($E$11:E23,"<>Chi*"),"00"),"") | D23: =IF(AND(LEFT(E23,3)="Chi",E23<>""),"PC2025/"&TEXT(COUNTIF($E$11:E23,"Chi*"),"00"),"") -> PC2025/11 | E23: Chi mừng sinh nhật đoàn viên Hứa Duy Anh Khoa | G23: 300000 | H23: =+H22+F23-G23 -> 289460 | K23: ok
A24: 45727 | B24: 45727 | C24: =IF(AND(LEFT(E24,3)<>"Chi",E24<>""),"PT2025/"&TEXT(COUNTIF($E$11:E24,"<>Chi*"),"00"),"") -> PT2025/03 | D24: =IF(AND(LEFT(E24,3)="Chi",E24<>""),"PC2025/"&TEXT(COUNTIF($E$11:E24,"Chi*"),"00"),"") | E24: Rút tiền gửi ngân hàng nhập quỹ tiền mặt | F24: 6000000 | H24: =+H23+F24-G24 -> 6289460
A25: 45727 | B25: 45727 | C25: =IF(AND(LEFT(E25,3)<>"Chi",E25<>""),"PT2025/"&TEXT(COUNTIF($E$11:E25,"<>Chi*"),"00"),"") | D25: =IF(AND(LEFT(E25,3)="Chi",E25<>""),"PC2025/"&TEXT(COUNTIF($E$11:E25,"Chi*"),"00"),"") -> PC2025/12 | E25: Chi mừng sinh nhật đoàn viên Tô Thị Ngọc Yến (07/03) | G25: 300000 | H25: =+H24+F25-G25 -> 5989460 | J25: x
A26: 45727 | B26: 45727 | C26: =IF(AND(LEFT(E26,3)<>"Chi",E26<>""),"PT2025/"&TEXT(COUNTIF($E$11:E26,"<>Chi*"),"00"),"") | D26: =IF(AND(LEFT(E26,3)="Chi",E26<>""),"PC2025/"&TEXT(COUNTIF($E$11:E26,"Chi*"),"00"),"") -> PC2025/13 | E26: Chi mừng lễ 08/03 cho đoàn viên nữ (18 người) | G26: 3600000 | H26: =+H25+F26-G26 -> 2389460
A27: 45734 | B27: 45734 | C27: =IF(AND(LEFT(E27,3)<>"Chi",E27<>""),"PT2025/"&TEXT(COUNTIF($E$11:E27,"<>Chi*"),"00"),"") | D27: =IF(AND(LEFT(E27,3)="Chi",E27<>""),"PC2025/"&TEXT(COUNTIF($E$11:E27,"Chi*"),"00"),"") -> PC2025/14 | E27: Chi mua văn phòng phẩm | G27: 800000 | H27: =+H26+F27-G27 -> 1589460 | J27: x
A28: 45735 | B28: 45735 | C28: =IF(AND(LEFT(E28,3)<>"Chi",E28<>""),"PT2025/"&TEXT(COUNTIF($E$11:E28,"<>Chi*"),"00"),"") | D28: =IF(AND(LEFT(E28,3)="Chi",E28<>""),"PC2025/"&TEXT(COUNTIF($E$11:E28,"Chi*"),"00"),"") -> PC2025/15 | E28: Chi mừng sinh nhật đoàn viên Trần Thị Ngọc Dung | G28: 300000 | H28: =+H27+F28-G28 -> 1289460 | J28: x
A29: 45738 | B29: 45738 | C29: =IF(AND(LEFT(E29,3)<>"Chi",E29<>""),"PT2025/"&TEXT(COUNTIF($E$11:E29,"<>Chi*"),"00"),"") | D29: =IF(AND(LEFT(E29,3)="Chi",E29<>""),"PC2025/"&TEXT(COUNTIF($E$11:E29,"Chi*"),"00"),"") -> PC2025/16 | E29: Chi mừng sinh nhật đoàn viên Huỳnh Pan Anh Trọng | G29: 300000 | H29: =+H28+F29-G29 -> 989460 | K29: ok
A30: 45748 | B30: 45748 | C30: =IF(AND(LEFT(E30,3)<>"Chi",E30<>""),"PT2025/"&TEXT(COUNTIF($E$11:E30,"<>Chi*"),"00"),"") -> PT2025/04 | D30: =IF(AND(LEFT(E30,3)="Chi",E30<>""),"PC2025/"&TEXT(COUNTIF($E$11:E30,"Chi*"),"00"),"") | E30: Thu đoàn phí công đoàn 1% quý 2 năm 2025 | F30: 7767300 | H30: =+H29+F30-G30 -> 8756760
A31: 45749 | B31: 45749 | C31: =IF(AND(LEFT(E31,3)<>"Chi",E31<>""),"PT2025/"&TEXT(COUNTIF($E$11:E31,"<>Chi*"),"00"),"") | D31: =IF(AND(LEFT(E31,3)="Chi",E31<>""),"PC2025/"&TEXT(COUNTIF($E$11:E31,"Chi*"),"00"),"") -> PC2025/17 | E31: Chi mừng sinh nhật đoàn viên Phạm Anh Minh | G31: 300000 | H31: =+H30+F31-G31 -> 8456760
A32: 45750 | B32: 45750 | C32: =IF(AND(LEFT(E32,3)<>"Chi",E32<>""),"PT2025/"&TEXT(COUNTIF($E$11:E32,"<>Chi*"),"00"),"") | D32: =IF(AND(LEFT(E32,3)="Chi",E32<>""),"PC2025/"&TEXT(COUNTIF($E$11:E32,"Chi*"),"00"),"") -> PC2025/18 | E32: Chi mừng sinh nhật đoàn viên Nguyễn Quốc Đạt | G32: 300000 | H32: =+H31+F32-G32 -> 8156760
A33: 45756 | B33: 45756 | C33: =IF(AND(LEFT(E33,3)<>"Chi",E33<>""),"PT2025/"&TEXT(COUNTIF($E$11:E33,"<>Chi*"),"00"),"") | D33: =IF(AND(LEFT(E33,3)="Chi",E33<>""),"PC2025/"&TEXT(COUNTIF($E$11:E33,"Chi*"),"00"),"") -> PC2025/19 | E33: Chi mừng sinh nhật đoàn viên Liên San | G33: 300000 | H33: =+H32+F33-G33 -> 7856760
A34: 45763 | B34: 45763 | C34: =IF(AND(LEFT(E34,3)<>"Chi",E34<>""),"PT2025/"&TEXT(COUNTIF($E$11:E34,"<>Chi*"),"00"),"") | D34: =IF(AND(LEFT(E34,3)="Chi",E34<>""),"PC2025/"&TEXT(COUNTIF($E$11:E34,"Chi*"),"00"),"") -> PC2025/20 | E34: Chi mừng sinh nhật đoàn viên Ngô Thị Bích Ngọc | G34: 300000 | H34: =+H33+F34-G34 -> 7556760
A35: 45763 | B35: 45763 | C35: =IF(AND(LEFT(E35,3)<>"Chi",E35<>""),"PT2025/"&TEXT(COUNTIF($E$11:E35,"<>Chi*"),"00"),"") | D35: =IF(AND(LEFT(E35,3)="Chi",E35<>""),"PC2025/"&TEXT(COUNTIF($E$11:E35,"Chi*"),"00"),"") -> PC2025/21 | E35: Chi mừng sinh nhật đoàn viên Trần Minh Thắng | G35: 300000 | H35: =+H34+F35-G35 -> 7256760
A36: 45764 | B36: 45764 | C36: =IF(AND(LEFT(E36,3)<>"Chi",E36<>""),"PT2025/"&TEXT(COUNTIF($E$11:E36,"<>Chi*"),"00"),"") | D36: =IF(AND(LEFT(E36,3)="Chi",E36<>""),"PC2025/"&TEXT(COUNTIF($E$11:E36,"Chi*"),"00"),"") -> PC2025/22 | E36: Chi mừng sinh nhật đoàn viên Nguyễn Bá Quân | G36: 300000 | H36: =+H35+F36-G36 -> 6956760
A37: 45776 | B37: 45776 | C37: =IF(AND(LEFT(E37,3)<>"Chi",E37<>""),"PT2025/"&TEXT(COUNTIF($E$11:E37,"<>Chi*"),"00"),"") -> PT2025/05 | D37: =IF(AND(LEFT(E37,3)="Chi",E37<>""),"PC2025/"&TEXT(COUNTIF($E$11:E37,"Chi*"),"00"),"") | E37: Rút tiền gửi ngân hàng nhập quỹ tiền mặt | F37: 3700000 | H37: =+H36+F37-G37 -> 10656760
A38: 45776 | B38: 45776 | C38: =IF(AND(LEFT(E38,3)<>"Chi",E38<>""),"PT2025/"&TEXT(COUNTIF($E$11:E38,"<>Chi*"),"00"),"") | D38: =IF(AND(LEFT(E38,3)="Chi",E38<>""),"PC2025/"&TEXT(COUNTIF($E$11:E38,"Chi*"),"00"),"") -> PC2025/23 | E38: Chi mừng lễ 30/04/2025 - 01/05/2025 cho đoàn viên (47 người) | G38: 9400000 | H38: =+H37+F38-G38 -> 1256760 | K38: ok
A39: 45779 | B39: 45779 | C39: =IF(AND(LEFT(E39,3)<>"Chi",E39<>""),"PT2025/"&TEXT(COUNTIF($E$11:E39,"<>Chi*"),"00"),"") | D39: =IF(AND(LEFT(E39,3)="Chi",E39<>""),"PC2025/"&TEXT(COUNTIF($E$11:E39,"Chi*"),"00"),"") -> PC2025/24 | E39: Chi mừng sinh nhật đoàn viên Nguyễn Kiên Hải | G39: 300000 | H39: =+H38+F39-G39 -> 956760
A40: 45784 | B40: 45784 | C40: =IF(AND(LEFT(E40,3)<>"Chi",E40<>""),"PT2025/"&TEXT(COUNTIF($E$11:E40,"<>Chi*"),"00"),"") | D40: =IF(AND(LEFT(E40,3)="Chi",E40<>""),"PC2025/"&TEXT(COUNTIF($E$11:E40,"Chi*"),"00"),"") -> PC2025/25 | E40: Chi mừng sinh nhật đoàn viên Nguyễn Trường Vũ | G40: 300000 | H40: =+H39+F40-G40 -> 656760
A41: 45784 | B41: 45784 | C41: =IF(AND(LEFT(E41,3)<>"Chi",E41<>""),"PT2025/"&TEXT(COUNTIF($E$11:E41,"<>Chi*"),"00"),"") | D41: =IF(AND(LEFT(E41,3)="Chi",E41<>""),"PC2025/"&TEXT(COUNTIF($E$11:E41,"Chi*"),"00"),"") -> PC2025/26 | E41: Chi mừng sinh nhật đoàn viên Lê Chí Thân | G41: 300000 | H41: =+H40+F41-G41 -> 356760
...

Sheet SỔ NH 2025 
A1: LIÊN ĐOÀN LAO ĐỘNG TP HỒ CHÍ MINH | H1: Mẫu số S12-H
A2: Công đoàn cơ sở: CTY TNHH TKXD & TM Hưng Phát | H2: (Ban hành kèm theo Thông tư số 107/2017/TT-BTC
H3: ngày 10/10/2017 của Bộ Tài chính)
A5: SỔ TIỀN GỬI NGÂN HÀNG
A6: Từ ngày 01/01/2025 đến ngày 31/12/2025
D7: Nơi mở tài khoản giao dịch:................
D8: Số hiệu tài khoản tại nơi gửi:..............
D9: Loại tiền gửi:.......................................
A11: Ngày tháng ghi sổ | B11: Chứng từ | D11: DIỄN GIẢI | G11: SỐ TIỀN | J11: Ghi chú
B12: Số hiệu | C12: Ngày tháng | G12: Thu (gửi vào) | H12: Chi (rút ra) | I12: Còn lại
A13: A | B13: B | C13: C | D13: D | G13: 1 | H13: 2 | I13: 3 | J13: E
D14: Số dư đầu kỳ | I14: 4041874
B15: UNC-01/2025 | C15: 45674 | D15: Thu phí dịch vụ IB Tháng 01/2025 | H15: 35000 | I15: =+I14+G15-H15 -> 4006874
B16: UNC-02/2025 | C16: 45674 | D16: VAT phí dịch vụ IB Tháng 01/2025 | H16: 3500 | I16: =+I15+G16-H16 -> 4003374
B17: BC-01/2025 | C17: 45680 | D17: Nhận 75% KPCĐ Cấp trên của Tháng 11 năm 2024 | G17: 4122600 | I17: =+I16+G17-H17 -> 8125974
B18: BC-02/2025 | C18: 45688 | D18: Lãi tiền gửi NH | G18: 864 | I18: =+I17+G18-H18 -> 8126838
B19: PT2025/02 | C19: 45691 | D19: Rút tiền gửi ngân hàng nhập quỹ tiền mặt | H19: 8000000 | I19: =+I18+G19-H19 -> 126838
B20: UNC-03/2025 | C20: 45705 | D20: Thu phí dịch vụ IB Tháng 02/2025 | H20: 35000 | I20: =+I19+G20-H20 -> 91838
B21: UNC-04/2025 | C21: 45705 | D21: VAT phí dịch vụ IB Tháng 02/2025 | H21: 3500 | I21: =+I20+G21-H21 -> 88338
B22: BC-03/2025 | C22: 45716 | D22: Lãi tiền gửi NH | G22: 149 | I22: =+I21+G22-H22 -> 88487
B23: BC-04/2025 | C23: 45726 | D23: Nhận 75% KPCĐ Cấp trên của Tháng 12 năm 2024 và Tháng 01 năm 2025 | G23: 8245200 | I23: =+I22+G23-H23 -> 8333687 | K23: x
B24: UNC-05/2025 | C24: 45727 | D24: Nộp 30% ĐPCĐ Tháng 01 năm 2025 | H24: 824520 | I24: =+I23+G24-H24 -> 7509167
B25: UNC-06/2025 | C25: 45727 | D25: Nộp 30% ĐPCĐ Tháng 02 năm 2025 | H25: 792660 | I25: =+I24+G25-H25 -> 6716507
B26: PT2025/03 | C26: 45727 | D26: Rút tiền gửi ngân hàng nhập quỹ tiền mặt | H26: 6000000 | I26: =+I25+G26-H26 -> 716507
B27: UNC-07/2025 | C27: 45733 | D27: Thu phí dịch vụ IB Tháng 03/2025 | H27: 35000 | I27: =+I26+G27-H27 -> 681507
B28: UNC-08/2025 | C28: 45733 | D28: VAT phí dịch vụ IB Tháng 03/2025 | H28: 3500 | I28: =+I27+G28-H28 -> 678007
B29: BC-05/2025 | C29: 45747 | D29: Lãi tiền gửi NH | G29: 126 | I29: =+I28+G29-H29 -> 678133
B30: UNC-09/2025 | C30: 45764 | D30: Thu phí dịch vụ IB Tháng 04/2025 | H30: 35000 | I30: =+I29+G30-H30 -> 643133
B31: UNC-10/2025 | C31: 45764 | D31: VAT phí dịch vụ IB Tháng 04/2025 | H31: 3500 | I31: =+I30+G31-H31 -> 639633
B32: BC-06/2025 | C32: 45771 | D32: Nhận 75% KPCĐ Cấp trên của Tháng 02 năm 2025 | G32: 3963300 | I32: =+I31+G32-H32 -> 4602933
B33: PT2025/05 | C33: 45776 | D33: Rút tiền gửi ngân hàng nhập quỹ tiền mặt | H33: 3700000 | I33: =+I32+G33-H33 -> 902933
B34: BC-07/2025 | C34: 45777 | D34: Lãi tiền gửi NH | G34: 219 | I34: =+I33+G34-H34 -> 903152
B35: UNC-11/2025 | C35: 45782 | D35: Nộp 30% ĐPCĐ Tháng 03 năm 2025 | H35: 776730 | I35: =+I34+G35-H35 -> 126422
B36: UNC-12/2025 | C36: 45794 | D36: Thu phí dịch vụ IB Tháng 05/2025 | H36: 35000 | I36: =+I35+G36-H36 -> 91422
B37: UNC-13/2025 | C37: 45794 | D37: VAT phí dịch vụ IB Tháng 05/2025 | H37: 3500 | I37: =+I36+G37-H37 -> 87922
B38: BC-08/2025 | C38: 45806 | D38: Nhận 75% KPCĐ Cấp trên của Tháng 03 năm 2025 | G38: 3883650 | I38: =+I37+G38-H38 -> 3971572
B39: BC-09/2025 | C39: 45808 | D39: Lãi tiền gửi NH | G39: 82 | I39: =+I38+G39-H39 -> 3971654
B40: UNC-14/2025 | C40: 45811 | D40: Nộp 30% ĐPCĐ Tháng 04 năm 2025 | H40: 776730 | I40: =+I39+G40-H40 -> 3194924
B41: PT2025/07 | C41: 45812 | D41: Rút tiền gửi ngân hàng nhập quỹ tiền mặt | H41: 3000000 | I41: =+I40+G41-H41 -> 194924
B42: UNC-15/2025 | C42: 45825 | D42: Thu phí dịch vụ IB Tháng 06/2025 | H42: 35000 | I42: =+I41+G42-H42 -> 159924
...

Sheet BANG KIEM KE TIEN MAT 2025
A2: Liên Đoàn Lao Động TP Hồ Chí Minh | D2: Mẫu số C34-HD
A3: CĐCS: Công Ty TNHH TK XD & TM Hưng Phát
A5: BIÊN BẢN KIỂM KÊ QUỸ TIỀN MẶT
A7: Hôm nay, ngày 31 tháng 12 năm 2025, vào hồi 13 giờ 30 phút.
A9: Ban kiểm kê bao gồm:
A10: Ông/Bà: Ngô Thị Bích Ngọc | C10: Chủ tịch CĐCS Trưởng Ban
A11: Ông/Bà: Nguyễn Thị Cẩm Ly | C11: Kế toán Ủy viên
A12: Ông/Bà: Võ Thị Mộng Thúy | C12: Thủ quỹ
A14: STT | B14: Diễn giải | C14: Số lượng (tờ) | D14: Số tiền | E14: KẾ TOÁN VÀ THỦ QUỸ PHẢI KIỂM VỚI NHAU TRÁCH SAI SÓT TIỀN
A15: A | B15: B | C15: 1 | D15: 2
A16: I | B16: Số dư theo số quỹ | D16: 438010 | E16: ghi theo số cuối kỳ sổ tiền mặt của báo cáo quyết toán
A17: II | B17: Số kiểm kê thực tế | D17: =+SUM(D18:D28) -> 438000 | E17: Ghi theo số kiểm kê tiền mặt tại quỹ do thủ quỹ giữ
A18: 1 | B18: - Loại 500.000đ
A19: 2 | B19: - Loại 200.000đ | C19: 2 | D19: =200000*C19 -> 400000
A20: 3 | B20: - Loại 100.000đ
A21: 4 | B21: - Loại 50.000đ
A22: 5 | B22: - Loại 20.000đ | C22: 1 | D22: 20000
A23: 6 | B23: - Loại 10.000đ | C23: 1 | D23: 10000
A24: 7 | B24: - Loại 5.000đ
A25: 8 | B25: - Loại 2.000đ | C25: 4 | D25: =2000*C25 -> 8000
A26: 9 | B26: - Loại 1.000đ
A27: 10 | B27: - Loại 500đ | E27: =+D17-D16 -> -10
A28: 7 | B28: - … | E28: lưu ý trên lệch không quá 500đ
A29: III | B29: Chênh lệch: | D29: =D17-D16 -> -10
A30: - Lý do: | B30: + Thiếu: 10đ
A31: - Kết luận sau khi kiểm quỹ: số tiền mặt kiểm tra thừa (thiếu) 10đ so với sổ sách do làm tròn số lẻ trong quá trình thu, chi.
B33: Kế toán | C33: Thủ quỹ | D33: Người chịu trách nhiệm kiểm kê quỹ
B34: (Ký, họ tên) | C34: (Ký, họ tên) | D34: (Ký, họ tên)
B39: Nguyễn Thị Cẩm Ly | C39: Võ Thị Mộng Thúy | D39: Ngô Thị Bích Ngọc

Sheet SỔ TM 2026
A1: LIÊN ĐOÀN LAO ĐỘNG TP HỒ CHÍ MINH | G1: Mẫu số S11H
A2: Công đoàn cơ sở: CTY TNHH TKXD & TM Hưng Phát | G2: (Ban hành kèm theo Thông tư số 107/2017/TT-BTC
G3: ngày 10/10/2017 của Bộ Tài chính)
B4: SỔ QUỸ TIỀN MẶT | J4: 1452000
B5: NĂM 2026
A7: Ngày tháng ghi sổ | B7: Ngày tháng chứng từ | C7: SỐ HIỆU CHỨNG TỪ | E7: DIỄN GIẢI | F7: SỐ TIỀN | I7: Ghi chú
C8: Thu | D8: Chi | F8: Thu | G8: Chi | H8: Tồn quỹ
A9: A | B9: B | C9: C | D9: D | E9: E | F9: 1 | G9: 2 | H9: 3 | I9: G
E10: Số dư đầu kỳ | H10: 438010
A11: 46037 | B11: 46037 | C11: =IF(AND(LEFT(E11,3)<>"Chi",E11<>""),"PT2026/"&TEXT(COUNTIF($E$11:E11,"<>Chi*"),"00"),"") | D11: =IF(AND(LEFT(E11,3)="Chi",E11<>""),"PC2026/"&TEXT(COUNTIF($E$11:E11,"Chi*"),"00"),"") -> PC2026/01 | E11: Chi mừng sinh nhật đoàn viên Nguyễn Thị Ngọc Trinh | G11: 300000 | H11: =H10+F11-G11 -> 138010
A12: 46175 | B12: 46175 | C12: =IF(AND(LEFT(E12,3)<>"Chi",E12<>""),"PT2026/"&TEXT(COUNTIF($E$11:E12,"<>Chi*"),"00"),"") -> PT2026/01 | D12: =IF(AND(LEFT(E12,3)="Chi",E12<>""),"PC2026/"&TEXT(COUNTIF($E$11:E12,"Chi*"),"00"),"") | E12: Thu đoàn phí công đoàn 0.5% quý 1 năm 2026 | F12: 3639150 | H12: =H11+F12-G12 -> 3777160
A13: 46175 | B13: 46175 | C13: =IF(AND(LEFT(E13,3)<>"Chi",E13<>""),"PT2026/"&TEXT(COUNTIF($E$11:E13,"<>Chi*"),"00"),"") | D13: =IF(AND(LEFT(E13,3)="Chi",E13<>""),"PC2026/"&TEXT(COUNTIF($E$11:E13,"Chi*"),"00"),"") -> PC2026/02 | E13: Chi mừng sinh nhật đoàn viên Nguyễn Thị Kỳ Duyên (31/01) | G13: 300000 | H13: =H12+F13-G13 -> 3477160
A14: 46175 | B14: 46175 | C14: =IF(AND(LEFT(E14,3)<>"Chi",E14<>""),"PT2026/"&TEXT(COUNTIF($E$11:E14,"<>Chi*"),"00"),"") -> PT2026/02 | D14: =IF(AND(LEFT(E14,3)="Chi",E14<>""),"PC2026/"&TEXT(COUNTIF($E$11:E14,"Chi*"),"00"),"") | E14: Thu bổ sung đoàn phí công đoàn 0.5% tháng 02+03 năm 2026 (đoàn viên Nguyễn Trường Vũ) | F14: 143000 | H14: =H13+F14-G14 -> 3620160
A15: 46063 | B15: 46063 | C15: =IF(AND(LEFT(E15,3)<>"Chi",E15<>""),"PT2026/"&TEXT(COUNTIF($E$11:E15,"<>Chi*"),"00"),"") -> PT2026/03 | D15: =IF(AND(LEFT(E15,3)="Chi",E15<>""),"PC2026/"&TEXT(COUNTIF($E$11:E15,"Chi*"),"00"),"") | E15: Rút tiền gửi ngân hàng nhập quỹ tiền mặt | F15: 5800000 | H15: =H14+F15-G15 -> 9420160
A16: 46063 | B16: 46063 | C16: =IF(AND(LEFT(E16,3)<>"Chi",E16<>""),"PT2026/"&TEXT(COUNTIF($E$11:E16,"<>Chi*"),"00"),"") | D16: =IF(AND(LEFT(E16,3)="Chi",E16<>""),"PC2026/"&TEXT(COUNTIF($E$11:E16,"Chi*"),"00"),"") -> PC2026/03 | E16: Chi mừng tết âm lịch cho đoàn viên (41 người - 200k/người) | G16: 8000000 | H16: =H15+F16-G16 -> 1420160
A17: 46065 | B17: 46065 | C17: =IF(AND(LEFT(E17,3)<>"Chi",E17<>""),"PT2026/"&TEXT(COUNTIF($E$11:E17,"<>Chi*"),"00"),"") | D17: =IF(AND(LEFT(E17,3)="Chi",E17<>""),"PC2026/"&TEXT(COUNTIF($E$11:E17,"Chi*"),"00"),"") -> PC2026/04 | E17: Chi mừng sinh nhật đoàn viên Bùi Xuân Mai Thảo | G17: 300000 | H17: =H16+F17-G17 -> 1120160
A18: 46076 | B18: 46076 | C18: =IF(AND(LEFT(E18,3)<>"Chi",E18<>""),"PT2026/"&TEXT(COUNTIF($E$11:E18,"<>Chi*"),"00"),"") | D18: =IF(AND(LEFT(E18,3)="Chi",E18<>""),"PC2026/"&TEXT(COUNTIF($E$11:E18,"Chi*"),"00"),"") -> PC2026/05 | E18: Chi mừng sinh nhật đoàn viên Huỳnh Thế Sơn (20/02) | G18: 300000 | H18: =H17+F18-G18 -> 820160
A19: 46145 | B19: 46145 | C19: =IF(AND(LEFT(E19,3)<>"Chi",E19<>""),"PT2026/"&TEXT(COUNTIF($E$11:E19,"<>Chi*"),"00"),"") | D19: =IF(AND(LEFT(E19,3)="Chi",E19<>""),"PC2026/"&TEXT(COUNTIF($E$11:E19,"Chi*"),"00"),"") -> PC2026/06 | E19: Chi mừng sinh nhật đoàn viên Nguyễn Luân Anh Vũ (05/03) | G19: 300000 | H19: =H18+F19-G19 -> 520160
A20: 46329 | B20: 46329 | C20: =IF(AND(LEFT(E20,3)<>"Chi",E20<>""),"PT2026/"&TEXT(COUNTIF($E$11:E20,"<>Chi*"),"00"),"") | D20: =IF(AND(LEFT(E20,3)="Chi",E20<>""),"PC2026/"&TEXT(COUNTIF($E$11:E20,"Chi*"),"00"),"") -> PC2026/07 | E20: Chi nộp tiền mặt vào tài khoản công đoàn | G20: 300000 | H20: =H19+F20-G20 -> 220160
A21: 46026 | B21: 46026 | C21: =IF(AND(LEFT(E21,3)<>"Chi",E21<>""),"PT2026/"&TEXT(COUNTIF($E$11:E21,"<>Chi*"),"00"),"") -> PT2026/04 | D21: =IF(AND(LEFT(E21,3)="Chi",E21<>""),"PC2026/"&TEXT(COUNTIF($E$11:E21,"Chi*"),"00"),"") | E21: Thu đoàn phí công đoàn 0.5% quý 2 năm 2026 | F21: 3967650 | H21: =H20+F21-G21 -> 4187810
A22: 46026 | B22: 46026 | C22: =IF(AND(LEFT(E22,3)<>"Chi",E22<>""),"PT2026/"&TEXT(COUNTIF($E$11:E22,"<>Chi*"),"00"),"") | D22: =IF(AND(LEFT(E22,3)="Chi",E22<>""),"PC2026/"&TEXT(COUNTIF($E$11:E22,"Chi*"),"00"),"") -> PC2026/08 | E22: Chi mừng lễ 08/03 cho đoàn viên nữ (18 người) | G22: 4000000 | H22: =H21+F22-G22 -> 187810
A23: 15/6/2026 | B23: 15/6/2026 | C23: =IF(AND(LEFT(E23,3)<>"Chi",E23<>""),"PT2026/"&TEXT(COUNTIF($E$11:E23,"<>Chi*"),"00"),"") -> PT2026/05 | D23: =IF(AND(LEFT(E23,3)="Chi",E23<>""),"PC2026/"&TEXT(COUNTIF($E$11:E23,"Chi*"),"00"),"") | E23: Rút tiền gửi ngân hàng nhập quỹ tiền mặt | F23: 15500000 | H23: =H22+F23-G23 -> 15687810
A24: 15/6/2026 | B24: 15/6/2026 | C24: =IF(AND(LEFT(E24,3)<>"Chi",E24<>""),"PT2026/"&TEXT(COUNTIF($E$11:E24,"<>Chi*"),"00"),"") | D24: =IF(AND(LEFT(E24,3)="Chi",E24<>""),"PC2026/"&TEXT(COUNTIF($E$11:E24,"Chi*"),"00"),"") -> PC2026/09 | E24: Chi mừng sinh nhật đoàn viên Tô Thị Ngọc Yến (07/03) | G24: 300000 | H24: =H23+F24-G24 -> 15387810
A25: 15/6/2026 | B25: 15/6/2026 | C25: =IF(AND(LEFT(E25,3)<>"Chi",E25<>""),"PT2026/"&TEXT(COUNTIF($E$11:E25,"<>Chi*"),"00"),"") | D25: =IF(AND(LEFT(E25,3)="Chi",E25<>""),"PC2026/"&TEXT(COUNTIF($E$11:E25,"Chi*"),"00"),"") -> PC2026/10 | E25: Chi mừng sinh nhật đoàn viên Trần Thị Ngọc Dung (19/03) | G25: 300000 | H25: =H24+F25-G25 -> 15087810
A26: 15/6/2026 | B26: 15/6/2026 | C26: =IF(AND(LEFT(E26,3)<>"Chi",E26<>""),"PT2026/"&TEXT(COUNTIF($E$11:E26,"<>Chi*"),"00"),"") | D26: =IF(AND(LEFT(E26,3)="Chi",E26<>""),"PC2026/"&TEXT(COUNTIF($E$11:E26,"Chi*"),"00"),"") -> PC2026/11 | E26: Chi mừng sinh nhật đoàn viên Lâm Nhật Quang (20/03) | G26: 300000 | H26: =H25+F26-G26 -> 14787810
A27: 15/6/2026 | B27: 15/6/2026 | C27: =IF(AND(LEFT(E27,3)<>"Chi",E27<>""),"PT2026/"&TEXT(COUNTIF($E$11:E27,"<>Chi*"),"00"),"") | D27: =IF(AND(LEFT(E27,3)="Chi",E27<>""),"PC2026/"&TEXT(COUNTIF($E$11:E27,"Chi*"),"00"),"") -> PC2026/12 | E27: Chi mừng sinh nhật đoàn viên Nguyễn Quốc Đạt (03/04) | G27: 300000 | H27: =H26+F27-G27 -> 14487810
A28: 15/6/2026 | B28: 15/6/2026 | C28: =IF(AND(LEFT(E28,3)<>"Chi",E28<>""),"PT2026/"&TEXT(COUNTIF($E$11:E28,"<>Chi*"),"00"),"") | D28: =IF(AND(LEFT(E28,3)="Chi",E28<>""),"PC2026/"&TEXT(COUNTIF($E$11:E28,"Chi*"),"00"),"") -> PC2026/13 | E28: Chi mừng sinh nhật đoàn viên Liên San (09/04) | G28: 300000 | H28: =H27+F28-G28 -> 14187810
A29: 15/6/2026 | B29: 15/6/2026 | C29: =IF(AND(LEFT(E29,3)<>"Chi",E29<>""),"PT2026/"&TEXT(COUNTIF($E$11:E29,"<>Chi*"),"00"),"") | D29: =IF(AND(LEFT(E29,3)="Chi",E29<>""),"PC2026/"&TEXT(COUNTIF($E$11:E29,"Chi*"),"00"),"") -> PC2026/14 | E29: Chi mừng sinh nhật đoàn viên Ngô Thị Bích Ngọc (16/04) | G29: 300000 | H29: =H28+F29-G29 -> 13887810
A30: 15/6/2026 | B30: 15/6/2026 | C30: =IF(AND(LEFT(E30,3)<>"Chi",E30<>""),"PT2026/"&TEXT(COUNTIF($E$11:E30,"<>Chi*"),"00"),"") | D30: =IF(AND(LEFT(E30,3)="Chi",E30<>""),"PC2026/"&TEXT(COUNTIF($E$11:E30,"Chi*"),"00"),"") -> PC2026/15 | E30: Chi mừng sinh nhật đoàn viên Trần Minh Thắng (16/04) | G30: 300000 | H30: =H29+F30-G30 -> 13587810
A31: 15/6/2026 | B31: 15/6/2026 | C31: =IF(AND(LEFT(E31,3)<>"Chi",E31<>""),"PT2026/"&TEXT(COUNTIF($E$11:E31,"<>Chi*"),"00"),"") | D31: =IF(AND(LEFT(E31,3)="Chi",E31<>""),"PC2026/"&TEXT(COUNTIF($E$11:E31,"Chi*"),"00"),"") -> PC2026/16 | E31: Chi mừng sinh nhật đoàn viên Nguyễn Bá Quân (17/04) | G31: 300000 | H31: =H30+F31-G31 -> 13287810
A32: 15/6/2026 | B32: 15/6/2026 | C32: =IF(AND(LEFT(E32,3)<>"Chi",E32<>""),"PT2026/"&TEXT(COUNTIF($E$11:E32,"<>Chi*"),"00"),"") | D32: =IF(AND(LEFT(E32,3)="Chi",E32<>""),"PC2026/"&TEXT(COUNTIF($E$11:E32,"Chi*"),"00"),"") -> PC2026/17 | E32: Chi mừng lễ 30/04/2026 - 01/05/2026 cho đoàn viên (41 người) | G32: 8000000 | H32: =H31+F32-G32 -> 5287810
A33: 15/6/2026 | B33: 15/6/2026 | C33: =IF(AND(LEFT(E33,3)<>"Chi",E33<>""),"PT2026/"&TEXT(COUNTIF($E$11:E33,"<>Chi*"),"00"),"") | D33: =IF(AND(LEFT(E33,3)="Chi",E33<>""),"PC2026/"&TEXT(COUNTIF($E$11:E33,"Chi*"),"00"),"") -> PC2026/18 | E33: Chi mừng sinh nhật đoàn viên Nguyễn Kiên Hải (02/05) | G33: 300000 | H33: =H32+F33-G33 -> 4987810
A34: 15/6/2026 | B34: 15/6/2026 | C34: =IF(AND(LEFT(E34,3)<>"Chi",E34<>""),"PT2026/"&TEXT(COUNTIF($E$11:E34,"<>Chi*"),"00"),"") | D34: =IF(AND(LEFT(E34,3)="Chi",E34<>""),"PC2026/"&TEXT(COUNTIF($E$11:E34,"Chi*"),"00"),"") -> PC2026/19 | E34: Chi mừng sinh nhật đoàn viên Nguyễn Trường Vũ (02/05) | G34: 300000 | H34: =H33+F34-G34 -> 4687810
A35: 15/6/2026 | B35: 15/6/2026 | C35: =IF(AND(LEFT(E35,3)<>"Chi",E35<>""),"PT2025/"&TEXT(COUNTIF($E$11:E35,"<>Chi*"),"00"),"") | D35: =IF(AND(LEFT(E35,3)="Chi",E35<>""),"PC2026/"&TEXT(COUNTIF($E$11:E35,"Chi*"),"00"),"") -> PC2026/20 | E35: Chi mừng sinh nhật đoàn viên Lê Chí Thân (07/05) | G35: 300000 | H35: =H34+F35-G35 -> 4387810
A36: 15/6/2026 | B36: 15/6/2026 | C36: =IF(AND(LEFT(E36,3)<>"Chi",E36<>""),"PT2025/"&TEXT(COUNTIF($E$11:E36,"<>Chi*"),"00"),"") | D36: =IF(AND(LEFT(E36,3)="Chi",E36<>""),"PC2025/"&TEXT(COUNTIF($E$11:E36,"Chi*"),"00"),"") -> PC2025/21 | E36: Chi mừng sinh nhật đoàn viên Lê Thị Hiếu Thư (16/05) | G36: 300000 | H36: =H35+F36-G36 -> 4087810
A37: 15/6/2026 | B37: 15/6/2026 | C37: =IF(AND(LEFT(E37,3)<>"Chi",E37<>""),"PT2025/"&TEXT(COUNTIF($E$11:E37,"<>Chi*"),"00"),"") | D37: =IF(AND(LEFT(E37,3)="Chi",E37<>""),"PC2025/"&TEXT(COUNTIF($E$11:E37,"Chi*"),"00"),"") -> PC2025/22 | E37: Chi mừng sinh nhật đoàn viên Ngô Tiến Đạt (25/05) | G37: 300000 | H37: =H36+F37-G37 -> 3787810
A38: 15/6/2026 | B38: 15/6/2026 | C38: =IF(AND(LEFT(E38,3)<>"Chi",E38<>""),"PT2025/"&TEXT(COUNTIF($E$11:E38,"<>Chi*"),"00"),"") | D38: =IF(AND(LEFT(E38,3)="Chi",E38<>""),"PC2025/"&TEXT(COUNTIF($E$11:E38,"Chi*"),"00"),"") -> PC2025/23 | E38: Chi mừng sinh nhật đoàn viên Dương Hồng Loan (28/05) | G38: 300000 | H38: =H37+F38-G38 -> 3487810
