Workbook
Name MaSo: [1]System!$B$10:$H$126
Name MaSo: [1]System!$B$10:$H$126
Name MaSo: [1]System!$B$10:$H$126
Name MaSo: [1]System!$B$10:$H$126
Name MaSo: [1]System!$B$10:$H$126
Name MaSo: [1]System!$B$10:$H$126
Name MaSo: [1]System!$B$10:$H$126
Name MaSo: [2]System!$B$10:$H$126

Sheet Tết dương lịch 2026
A1: CĐCS: Công Ty TNHH TK XD & TM Hưng Phát
A3: Danh Sách thưởng Lễ Tết Dương Lịch 2025
A5: STT | B5: Họ & tên | C5: Mức thưởng | D5: Ký nhận
A7: 1 | B7: Trần Minh Thắng | C7: 200000
A8: 2 | B8: Lê Hoàng Sỹ | C8: 200000
A9: 3 | B9: Dương Hồng Loan | C9: 200000
A10: 4 | B10: Lê Chí Thân | C10: 200000
A11: 5 | B11: Nguyễn Văn Hây | C11: 200000
A12: 6 | B12: Võ Huy Phong | C12: 200000
A13: 7 | B13: Nguyễn Bá Thành | C13: 200000
A14: 8 | B14: Vòng Và Tuấn | C14: 200000
A15: 9 | B15: Nguyễn Nguyên Hùng | C15: 200000
A16: 10 | B16: Trần Thị Ngọc Dung | C16: 200000
A17: 11 | B17: Cao Đình Dương | C17: 200000
A18: 12 | B18: Thái Trung Dũng | C18: 200000
... A45: 39 | B45: Nguyễn Thị Cẩm Ly | C45: 200000
B47: Tổng | C47: =SUM(C7:C46) -> 7800000
D50: Quận Tân Phú, Ngày31 tháng 12 năm 2024
D51: TM Ban Chấp Hành
B52: Người lập | D52: Chủ tịch
B57: Nguyễn Thị Cẩm Ly | D57: Ngô Thị Bích Ngọc

Sheet Tet 2026
A1: CĐCS: Công Ty TNHH TK XD & TM Hưng Phát
A3: Danh Sách thưởng Tết âm lịch năm 2026
A5: STT | B5: Họ & tên | C5: Mức thưởng | D5: Ký nhận
A7: 1 | B7: Trần Minh Thắng | C7: 200000
A8: 2 | B8: Lê Hoàng Sỹ | C8: 200000
A9: 3 | B9: Dương Hồng Loan | C9: 200000
A10: 4 | B10: Lê Chí Thân | C10: 200000
A11: 5 | B11: Nguyễn Văn Hây | C11: 200000
A12: 6 | B12: Võ Huy Phong | C12: 200000
A13: 7 | B13: Nguyễn Bá Thành | C13: 200000
A14: 8 | B14: Vòng Và Tuấn | C14: 200000
A15: 9 | B15: Nguyễn Nguyên Hùng | C15: 200000
A16: 10 | B16: Trần Thị Ngọc Dung | C16: 200000
A17: 11 | B17: Cao Đình Dương | C17: 200000
A18: 12 | B18: Thái Trung Dũng | C18: 200000
... A46: 40 | B46: Lê Thị Hiếu Thư | C46: 200000
B48: Tổng | C48: =SUM(C7:C47) -> 8000000
D51: Quận Tân Phú, Ngày 03 tháng 02 năm 2025
D52: TM Ban Chấp Hành
B53: Người lập | D53: Chủ tịch
B58: Nguyễn Thị Cẩm Ly | D58: Ngô Thị Bích Ngọc

Sheet 8.3
A1: CĐCS: Công Ty TNHH TK XD & TM Hưng Phát
A3: Danh Sách thưởng Lễ 08/03/2026
A5: STT | B5: Họ & tên | C5: Mức thưởng | D5: Ký nhận
A7: 1 | B7: Dương Hồng Loan | C7: 200000
A8: 2 | B8: Trần Thị Ngọc Dung | C8: 200000
A9: 3 | B9: Nguyễn Thị Nhung | C9: 200000
A10: 4 | B10: Võ Thị Mộng Thúy | C10: 200000
A11: 5 | B11: Liên San | C11: 200000
A12: 6 | B12: Nguyễn Thị Ngọc Trinh | C12: 200000
A13: 7 | B13: Ngô Thị Bích Ngọc | C13: 200000
A14: 8 | B14: Tô Thị Ngọc Yến | C14: 200000
A15: 9 | B15: Trần Thuận Châu | C15: 200000
A16: 10 | B16: Ngô Thị Tuyết | C16: 200000
A17: 11 | B17: Lê Thị Thu Thảo | C17: 200000
A18: 12 | B18: Bùi Xuân Mai Thảo | C18: 200000
... A26: 20 | B26: Lê Thị Nhã Mi | C26: 200000
B28: Tổng | C28: =SUM(C7:C27) -> 4000000
D31: Quận Tân Phú, Ngày 08 tháng 03 năm 2026
D32: TM Ban Chấp Hành
B33: Người lập | D33: Chủ tịch
B38: Nguyễn Thị Cẩm Ly | D38: Ngô Thị Bích Ngọc

Sheet 30-04
A1: CĐCS: Công Ty TNHH TK XD & TM Hưng Phát
A3: Danh Sách thưởng lễ 30/04 và 01/05/2025
A5: STT | B5: Họ & tên | C5: Mức thưởng | D5: Ký nhận
A7: 1 | B7: Trần Minh Thắng | C7: 200000
A8: 2 | B8: Lê Hoàng Sỹ | C8: 200000
A9: 3 | B9: Dương Hồng Loan | C9: 200000
A10: 4 | B10: Lê Chí Thân | C10: 200000
A11: 5 | B11: Nguyễn Văn Hây | C11: 200000
A12: 6 | B12: Võ Huy Phong | C12: 200000
A13: 7 | B13: Nguyễn Bá Thành | C13: 200000
A14: 8 | B14: Vòng Và Tuấn | C14: 200000
A15: 9 | B15: Nguyễn Nguyên Hùng | C15: 200000
A16: 10 | B16: Trần Thị Ngọc Dung | C16: 200000
A17: 11 | B17: Cao Đình Dương | C17: 200000
A18: 12 | B18: Thái Trung Dũng | C18: 200000
... A46: 41 | B46: Ngô Thị Ngọc Dung | C46: 200000
B48: Tổng | C48: =SUM(C7:C47) -> 8000000
D51: Quận Tân Phú, Ngày 29 tháng 04 năm 2025
D52: TM Ban Chấp Hành
B53: Người lập | D53: Chủ tịch
B58: Nguyễn Thị Cẩm Ly | D58: Ngô Thị Bích Ngọc

Sheet 02-09
A1: CĐCS: Công Ty TNHH TK XD & TM Hưng Phát
A3: Danh Sách thưởng lễ 02/09/2025
A5: STT | B5: Họ & tên | C5: Mức thưởng | D5: Ký nhận
A7: 1 | B7: Trần Minh Thắng | C7: 100000
A8: 2 | B8: Lê Hoàng Sỹ | C8: 100000
A9: 3 | B9: Dương Hồng Loan | C9: 100000
A10: 4 | B10: Lê Chí Thân | C10: 100000
A11: 5 | B11: Nguyễn Văn Hây | C11: 100000
A12: 6 | B12: Võ Huy Phong | C12: 100000
A13: 7 | B13: Nguyễn Bá Thành | C13: 100000
A14: 8 | B14: Vòng Và Tuấn | C14: 100000
A15: 9 | B15: Nguyễn Nguyên Hùng | C15: 100000
A16: 10 | B16: Trần Thị Ngọc Dung | C16: 100000
A17: 11 | B17: Cao Đình Dương | C17: 100000
A18: 12 | B18: Thái Trung Dũng | C18: 100000
... A55: 49 | B55: Nguyễn Thị Cẩm Ly | C55: 100000
B57: Tổng | C57: =SUM(C7:C56) -> 4900000
D60: Quận Tân Phú, Ngày 23 tháng 09 năm 2025
D61: TM Ban Chấp Hành
B62: Người lập | D62: Chủ tịch
B67: Nguyễn Thị Cẩm Ly | D67: Ngô Thị Bích Ngọc

Sheet Trung thu
A1: CĐCS: Công Ty TNHH TK XD & TM Hưng Phát
A3: Danh Sách Mừmg Tết Trung Thu Con Đoàn Viên
A5: STT | B5: Họ Và Tên Đoàn Viên | C5: Họ Và Tên Con Đoàn Viên | D5: Số Tiền | E5: Ký Nhận
A6: 1 | B6: Nguyễn Quốc Đạt | C6: Nguyễn Ngọc An Vy | D6: 100000
A7: 2 | B7: Nguyễn Quốc Đạt | C7: Nguyễn Tuấn Khải | D7: 100000
A8: 3 | B8: Ngoâ Thị Bích Ngọc | C8: Ngoâ Höõu Khoa | D8: 100000
A9: 4 | B9: Leâ Vaên Ñieàn | C9: Leâ Nguyễn Khắc Triệu | D9: 100000
A10: 5 | B10: Nguyeãn Thò Thuùy Haèng | C10: Caùt Anh | D10: 100000
A11: 6 | B11: Nguyễn Thị Ngọc Trinh | C11: Leâê Nguyễn Hải Triều | D11: 100000
A12: 7 | B12: Ngoâ Tieán Ñaït | C12: Ngoâ Vuõ Quyønh Lam | D12: 100000
B14: Tổng | D14: =SUM(D6:D13) -> 700000
E17: Quận Tân Phú, Ngày 13 tháng 09 năm 2024
E18: TM Ban Chấp Hành
B19: Người lập | E19: Chủ tịch
B24: Ngô Thị Bích Ngọc | E24: Nguyễn Thị Thúy Hằng

Sheet 20.10
A1: CĐCS: Công Ty TNHH TK XD & TM Hưng Phát
A3: Danh Sách thưởng Lễ 20/10/2025
A5: STT | B5: Họ & tên | C5: Mức thưởng | D5: Ký nhận
A7: 1 | B7: Dương Hồng Loan | C7: 200000
A8: 2 | B8: Trần Thị Ngọc Dung | C8: 200000
A9: 3 | B9: Nguyễn Thị Nhung | C9: 200000
A10: 4 | B10: Võ Thị Mộng Thúy | C10: 200000
A11: 5 | B11: Liên San | C11: 200000
A12: 6 | B12: Nguyễn Thị Ngọc Trinh | C12: 200000
A13: 7 | B13: Ngô Thị Bích Ngọc | C13: 200000
A14: 8 | B14: Tô Thị Ngọc Yến | C14: 200000
A15: 9 | B15: Trần Thuận Châu | C15: 200000
A16: 10 | B16: Sử Ngọc Quế | C16: 200000
A17: 11 | B17: Ngô Thị Tuyết | C17: 200000
A18: 12 | B18: Lê Thị Thu Thảo | C18: 200000
... A23: 17 | B23: Nguyễn Thị Cẩm Ly | C23: 200000
B25: Tổng | C25: =SUM(C7:C24) -> 3400000
D28: Quận Tân Phú, Ngày 20 tháng 10 năm 2025
D29: TM Ban Chấp Hành
B30: Người lập | D30: Chủ tịch
B35: Nguyễn Thị Cẩm Ly | D35: Ngô Thị Bích Ngọc

Sheet 012026
A1: Hung Phat Co., Ltd
J2: Theo quyết định số 61/QĐ-TLĐ ngày 29/07/2025
A3: Danh Sách Trích Nộp Phí Công Đoàn Tháng 01/2026 | J3: Thay đổi mức đóng đoàn phí hằng tháng là 0.5%
J4: bắt đầu có hiệu lực từ ngày 01/07/2025
A5: STT | B5: Họ & tên | C5: Mức lương đóng | D5: Trích đóng 2% | F5: Trích đóng 0.5% đoàn phí công đoàn | H5: Tổng cộng | J5: bắt đầu từ tháng 10 bỏ 9 mã số (2301, 2302, 2303, 2305, 2307, 2308, 2313, 2315, 2316)
D6: Công đoàn Cty giữ 75% | E6: Liên đoàn VN giữ 25% | F6: Công đoàn Cty giữ 70% | G6: Liên đoàn QTP giữ 30% | J6: V105 nghỉ thai sản
A7: 1 | B7: Trần Minh Thắng | C7: 5700000 | D7: =C7*0.02*0.75 -> 85500 | E7: =C7*0.02*0.25 -> 28500 | F7: =C7*0.005*0.7 -> 19950 | G7: =C7*0.005*0.3 -> 8550 | H7: =C7*0.03 -> 171000 | J7: Thêm 1518
A8: 2 | B8: Lê Hoàng Sỹ | C8: 5700000 | D8: =C8*0.02*0.75 -> 85500 | E8: =C8*0.02*0.25 -> 28500 | F8: =C8*0.005*0.7 -> 19950 | G8: =C8*0.005*0.3 -> 8550 | H8: =C8*0.03 -> 171000
A9: 3 | B9: Dương Hồng Loan | C9: 5700000 | D9: =C9*0.02*0.75 -> 85500 | E9: =C9*0.02*0.25 -> 28500 | F9: =C9*0.005*0.7 -> 19950 | G9: =C9*0.005*0.3 -> 8550 | H9: =C9*0.03 -> 171000
A10: 4 | B10: Lê Chí Thân | C10: 5700000 | D10: =C10*0.02*0.75 -> 85500 | E10: =C10*0.02*0.25 -> 28500 | F10: =C10*0.005*0.7 -> 19950 | G10: =C10*0.005*0.3 -> 8550 | H10: =C10*0.03 -> 171000
A11: 5 | B11: Nguyễn Văn Hây | C11: 5700000 | D11: =C11*0.02*0.75 -> 85500 | E11: =C11*0.02*0.25 -> 28500 | F11: =C11*0.005*0.7 -> 19950 | G11: =C11*0.005*0.3 -> 8550 | H11: =C11*0.03 -> 171000
A12: 6 | B12: Võ Huy Phong | C12: 5700000 | D12: =C12*0.02*0.75 -> 85500 | E12: =C12*0.02*0.25 -> 28500 | F12: =C12*0.005*0.7 -> 19950 | G12: =C12*0.005*0.3 -> 8550 | H12: =C12*0.03 -> 171000
A13: 7 | B13: Nguyễn Bá Thành | C13: 5700000 | D13: =C13*0.02*0.75 -> 85500 | E13: =C13*0.02*0.25 -> 28500 | F13: =C13*0.005*0.7 -> 19950 | G13: =C13*0.005*0.3 -> 8550 | H13: =C13*0.03 -> 171000
A14: 8 | B14: Vòng Và Tuấn | C14: 5700000 | D14: =C14*0.02*0.75 -> 85500 | E14: =C14*0.02*0.25 -> 28500 | F14: =C14*0.005*0.7 -> 19950 | G14: =C14*0.005*0.3 -> 8550 | H14: =C14*0.03 -> 171000
A15: 9 | B15: Nguyễn Nguyên Hùng | C15: 5700000 | D15: =C15*0.02*0.75 -> 85500 | E15: =C15*0.02*0.25 -> 28500 | F15: =C15*0.005*0.7 -> 19950 | G15: =C15*0.005*0.3 -> 8550 | H15: =C15*0.03 -> 171000
A16: 10 | B16: Trần Thị Ngọc Dung | C16: 5700000 | D16: =C16*0.02*0.75 -> 85500 | E16: =C16*0.02*0.25 -> 28500 | F16: =C16*0.005*0.7 -> 19950 | G16: =C16*0.005*0.3 -> 8550 | H16: =C16*0.03 -> 171000
A17: 11 | B17: Cao Đình Dương | C17: 5700000 | D17: =C17*0.02*0.75 -> 85500 | E17: =C17*0.02*0.25 -> 28500 | F17: =C17*0.005*0.7 -> 19950 | G17: =C17*0.005*0.3 -> 8550 | H17: =C17*0.03 -> 171000
A18: 12 | B18: Thái Trung Dũng | C18: 5700000 | D18: =C18*0.02*0.75 -> 85500 | E18: =C18*0.02*0.25 -> 28500 | F18: =C18*0.005*0.7 -> 19950 | G18: =C18*0.005*0.3 -> 8550 | H18: =C18*0.03 -> 171000
A19: 13 | B19: Trần Văn Hiếu | C19: 5700000 | D19: =C19*0.02*0.75 -> 85500 | E19: =C19*0.02*0.25 -> 28500 | F19: =C19*0.005*0.7 -> 19950 | G19: =C19*0.005*0.3 -> 8550 | H19: =C19*0.03 -> 171000
... A35: 29 | B35: Ngô Thị Tuyết | C35: 5700000 | D35: =C35*0.02*0.75 -> 85500 | E35: =C35*0.02*0.25 -> 28500 | F35: =C35*0.005*0.7 -> 19950 | G35: =C35*0.005*0.3 -> 8550 | H35: =C35*0.03 -> 171000
A36: 30 | B36: Nguyễn Trường Vũ | C36: 5700000 | D36: =C36*0.02*0.75 -> 85500 | E36: =C36*0.02*0.25 -> 28500 | F36: =C36*0.005*0.7 -> 19950 | G36: =C36*0.005*0.3 -> 8550 | H36: =C36*0.03 -> 171000 | I36: =+H36+'02026'!H36+'032026'!H36 -> 1371000
A37: 31 | B37: Lê Thị Thu Thảo | C37: 5700000 | D37: =C37*0.02*0.75 -> 85500 | E37: =C37*0.02*0.25 -> 28500 | F37: =C37*0.005*0.7 -> 19950 | G37: =C37*0.005*0.3 -> 8550 | H37: =C37*0.03 -> 171000
A38: 32 | B38: Lâm Nhật Quang | C38: 5700000 | D38: =C38*0.02*0.75 -> 85500 | E38: =C38*0.02*0.25 -> 28500 | F38: =C38*0.005*0.7 -> 19950 | G38: =C38*0.005*0.3 -> 8550 | H38: =C38*0.03 -> 171000
A39: 33 | B39: Bùi Xuân Mai Thảo | C39: 5700000 | D39: =C39*0.02*0.75 -> 85500 | E39: =C39*0.02*0.25 -> 28500 | F39: =C39*0.005*0.7 -> 19950 | G39: =C39*0.005*0.3 -> 8550 | H39: =C39*0.03 -> 171000
A40: 34 | B40: Nguyễn Quốc Cảnh | C40: 5700000 | D40: =C40*0.02*0.75 -> 85500 | E40: =C40*0.02*0.25 -> 28500 | F40: =C40*0.005*0.7 -> 19950 | G40: =C40*0.005*0.3 -> 8550 | H40: =C40*0.03 -> 171000
A41: 35 | B41: Huỳnh Thế Sơn | C41: 5700000 | D41: =C41*0.02*0.75 -> 85500 | E41: =C41*0.02*0.25 -> 28500 | F41: =C41*0.005*0.7 -> 19950 | G41: =C41*0.005*0.3 -> 8550 | H41: =C41*0.03 -> 171000
A42: 36 | B42: Nguyễn Thị Kỳ Duyên | C42: 5700000 | D42: =C42*0.02*0.75 -> 85500 | E42: =C42*0.02*0.25 -> 28500 | F42: =C42*0.005*0.7 -> 19950 | G42: =C42*0.005*0.3 -> 8550 | H42: =C42*0.03 -> 171000
A43: 37 | B43: Nguyễn Thị Mai Thi | C43: 5700000 | D43: =C43*0.02*0.75 -> 85500 | E43: =C43*0.02*0.25 -> 28500 | F43: =C43*0.005*0.7 -> 19950 | G43: =C43*0.005*0.3 -> 8550 | H43: =C43*0.03 -> 171000
A44: 38 | B44: Nông Hoàng Phát | C44: 5700000 | D44: =C44*0.02*0.75 -> 85500 | E44: =C44*0.02*0.25 -> 28500 | F44: =C44*0.005*0.7 -> 19950 | G44: =C44*0.005*0.3 -> 8550 | H44: =C44*0.03 -> 171000
A45: 39 | B45: Lê Thị Nhã Mi | C45: 0 | D45: =C45*0.02*0.75 -> 0 | E45: =C45*0.02*0.25 -> 0 | F45: =C45*0.005*0.7 -> 0 | G45: =C45*0.005*0.3 -> 0 | H45: =C45*0.03 -> 0 | I45: Nghỉ thai sản
A46: 40 | B46: Nguyễn Thị Cẩm Ly | C46: 5700000 | D46: =C46*0.02*0.75 -> 85500 | E46: =C46*0.02*0.25 -> 28500 | F46: =C46*0.005*0.7 -> 19950 | G46: =C46*0.005*0.3 -> 8550 | H46: =C46*0.03 -> 171000
A47: 41 | B47: Lê Thị Hiếu Thư | C47: 5700000 | D47: =C47*0.02*0.75 -> 85500 | E47: =C47*0.02*0.25 -> 28500 | F47: =C47*0.005*0.7 -> 19950 | G47: =C47*0.005*0.3 -> 8550 | H47: =C47*0.03 -> 171000
A48: 42 | B48: Bùi Thị Kim Chi | C48: 5700000 | D48: =C48*0.02*0.75 -> 85500 | E48: =C48*0.02*0.25 -> 28500 | F48: =C48*0.005*0.7 -> 19950 | G48: =C48*0.005*0.3 -> 8550 | H48: =C48*0.03 -> 171000
B50: Tổng | C50: =SUM(C7:C49) -> 242610000 | D50: =SUM(D7:D49) -> 3639150 | E50: =SUM(E7:E49) -> 1213050 | F50: =SUM(F7:F49) -> 849135 | G50: =SUM(G7:G49) -> 363915 | H50: =SUM(H7:H49) -> 7278300
D51: =+D50+E50 -> 4852200
E53: Ngày 01 tháng 01 năm 2026
E54: Người lập
E59: Nguyễn Thị Cẩm Ly

Sheet 02026
A1: Hung Phat Co., Ltd
J2: Theo quyết định số 61/QĐ-TLĐ ngày 29/07/2025
A3: Danh Sách Trích Nộp Phí Công Đoàn Tháng 02/2026 | J3: Thay đổi mức đóng đoàn phí hằng tháng là 0.5%
J4: bắt đầu có hiệu lực từ ngày 01/07/2025
A5: STT | B5: Họ & tên | C5: Mức lương đóng | D5: Trích đóng 2% | F5: Trích đóng 0.5% đoàn phí công đoàn | H5: Tổng cộng | J5: bắt đầu từ tháng 10 bỏ 9 mã số (2301, 2302, 2303, 2305, 2307, 2308, 2313, 2315, 2316)
D6: Công đoàn Cty giữ 75% | E6: Liên đoàn VN giữ 25% | F6: Công đoàn Cty giữ 70% | G6: Liên đoàn QTP giữ 30% | J6: V105 nghỉ thai sản
A7: 1 | B7: Trần Minh Thắng | C7: 5700000 | D7: =C7*0.02*0.75 -> 85500 | E7: =C7*0.02*0.25 -> 28500 | F7: =C7*0.005*0.7 -> 19950 | G7: =C7*0.005*0.3 -> 8550 | H7: =C7*0.03 -> 171000 | J7: Thêm 1518
A8: 2 | B8: Lê Hoàng Sỹ | C8: 5700000 | D8: =C8*0.02*0.75 -> 85500 | E8: =C8*0.02*0.25 -> 28500 | F8: =C8*0.005*0.7 -> 19950 | G8: =C8*0.005*0.3 -> 8550 | H8: =C8*0.03 -> 171000
A9: 3 | B9: Dương Hồng Loan | C9: 5700000 | D9: =C9*0.02*0.75 -> 85500 | E9: =C9*0.02*0.25 -> 28500 | F9: =C9*0.005*0.7 -> 19950 | G9: =C9*0.005*0.3 -> 8550 | H9: =C9*0.03 -> 171000 | I9: X
A10: 4 | B10: Lê Chí Thân | C10: 5700000 | D10: =C10*0.02*0.75 -> 85500 | E10: =C10*0.02*0.25 -> 28500 | F10: =C10*0.005*0.7 -> 19950 | G10: =C10*0.005*0.3 -> 8550 | H10: =C10*0.03 -> 171000
A11: 5 | B11: Nguyễn Văn Hây | C11: 5700000 | D11: =C11*0.02*0.75 -> 85500 | E11: =C11*0.02*0.25 -> 28500 | F11: =C11*0.005*0.7 -> 19950 | G11: =C11*0.005*0.3 -> 8550 | H11: =C11*0.03 -> 171000
A12: 6 | B12: Võ Huy Phong | C12: 5700000 | D12: =C12*0.02*0.75 -> 85500 | E12: =C12*0.02*0.25 -> 28500 | F12: =C12*0.005*0.7 -> 19950 | G12: =C12*0.005*0.3 -> 8550 | H12: =C12*0.03 -> 171000
A13: 7 | B13: Nguyễn Bá Thành | C13: 5700000 | D13: =C13*0.02*0.75 -> 85500 | E13: =C13*0.02*0.25 -> 28500 | F13: =C13*0.005*0.7 -> 19950 | G13: =C13*0.005*0.3 -> 8550 | H13: =C13*0.03 -> 171000
A14: 8 | B14: Vòng Và Tuấn | C14: 5700000 | D14: =C14*0.02*0.75 -> 85500 | E14: =C14*0.02*0.25 -> 28500 | F14: =C14*0.005*0.7 -> 19950 | G14: =C14*0.005*0.3 -> 8550 | H14: =C14*0.03 -> 171000
A15: 9 | B15: Nguyễn Nguyên Hùng | C15: 5700000 | D15: =C15*0.02*0.75 -> 85500 | E15: =C15*0.02*0.25 -> 28500 | F15: =C15*0.005*0.7 -> 19950 | G15: =C15*0.005*0.3 -> 8550 | H15: =C15*0.03 -> 171000
A16: 10 | B16: Trần Thị Ngọc Dung | C16: 5700000 | D16: =C16*0.02*0.75 -> 85500 | E16: =C16*0.02*0.25 -> 28500 | F16: =C16*0.005*0.7 -> 19950 | G16: =C16*0.005*0.3 -> 8550 | H16: =C16*0.03 -> 171000 | I16: X
A17: 11 | B17: Cao Đình Dương | C17: 5700000 | D17: =C17*0.02*0.75 -> 85500 | E17: =C17*0.02*0.25 -> 28500 | F17: =C17*0.005*0.7 -> 19950 | G17: =C17*0.005*0.3 -> 8550 | H17: =C17*0.03 -> 171000
A18: 12 | B18: Thái Trung Dũng | C18: 5700000 | D18: =C18*0.02*0.75 -> 85500 | E18: =C18*0.02*0.25 -> 28500 | F18: =C18*0.005*0.7 -> 19950 | G18: =C18*0.005*0.3 -> 8550 | H18: =C18*0.03 -> 171000
A19: 13 | B19: Trần Văn Hiếu | C19: 5700000 | D19: =C19*0.02*0.75 -> 85500 | E19: =C19*0.02*0.25 -> 28500 | F19: =C19*0.005*0.7 -> 19950 | G19: =C19*0.005*0.3 -> 8550 | H19: =C19*0.03 -> 171000
A20: 14 | B20: Nguyễn Thị Nhung | C20: 5700000 | D20: =C20*0.02*0.75 -> 85500 | E20: =C20*0.02*0.25 -> 28500 | F20: =C20*0.005*0.7 -> 19950 | G20: =C20*0.005*0.3 -> 8550 | H20: =C20*0.03 -> 171000 | I20: X
A21: 15 | B21: Võ Thị Mộng Thúy | C21: 5700000 | D21: =C21*0.02*0.75 -> 85500 | E21: =C21*0.02*0.25 -> 28500 | F21: =C21*0.005*0.7 -> 19950 | G21: =C21*0.005*0.3 -> 8550 | H21: =C21*0.03 -> 171000 | I21: X
A22: 16 | B22: Lê Văn Điền | C22: 5700000 | D22: =C22*0.02*0.75 -> 85500 | E22: =C22*0.02*0.25 -> 28500 | F22: =C22*0.005*0.7 -> 19950 | G22: =C22*0.005*0.3 -> 8550 | H22: =C22*0.03 -> 171000
A23: 17 | B23: Nguyễn Luân Anh Vũ | C23: 5700000 | D23: =C23*0.02*0.75 -> 85500 | E23: =C23*0.02*0.25 -> 28500 | F23: =C23*0.005*0.7 -> 19950 | G23: =C23*0.005*0.3 -> 8550 | H23: =C23*0.03 -> 171000
A24: 18 | B24: Liên San | C24: 5700000 | D24: =C24*0.02*0.75 -> 85500 | E24: =C24*0.02*0.25 -> 28500 | F24: =C24*0.005*0.7 -> 19950 | G24: =C24*0.005*0.3 -> 8550 | H24: =C24*0.03 -> 171000 | I24: X
A25: 19 | B25: Nguyễn Thị Ngọc Trinh | C25: 5700000 | D25: =C25*0.02*0.75 -> 85500 | E25: =C25*0.02*0.25 -> 28500 | F25: =C25*0.005*0.7 -> 19950 | G25: =C25*0.005*0.3 -> 8550 | H25: =C25*0.03 -> 171000 | I25: X
A26: 20 | B26: Ngô Thị Bích Ngọc | C26: 15000000 | D26: =C26*0.02*0.75 -> 225000 | E26: =C26*0.02*0.25 -> 75000 | F26: =C26*0.005*0.7 -> 52500 | G26: =C26*0.005*0.3 -> 22500 | H26: =C26*0.03 -> 450000 | I26: X
A27: 21 | B27: Ngô Tiến Đạt | C27: 5700000 | D27: =C27*0.02*0.75 -> 85500 | E27: =C27*0.02*0.25 -> 28500 | F27: =C27*0.005*0.7 -> 19950 | G27: =C27*0.005*0.3 -> 8550 | H27: =C27*0.03 -> 171000
A28: 22 | B28: Nguyễn Quốc Đạt | C28: 5700000 | D28: =C28*0.02*0.75 -> 85500 | E28: =C28*0.02*0.25 -> 28500 | F28: =C28*0.005*0.7 -> 19950 | G28: =C28*0.005*0.3 -> 8550 | H28: =C28*0.03 -> 171000
A29: 23 | B29: Tô Thị Ngọc Yến | C29: 5310000 | D29: =C29*0.02*0.75 -> 79650 | E29: =C29*0.02*0.25 -> 26550 | F29: =C29*0.005*0.7 -> 18585 | G29: =C29*0.005*0.3 -> 7965 | H29: =C29*0.03 -> 159300 | I29: X
A30: 24 | B30: Nguyễn Kiên Hải | C30: 5700000 | D30: =C30*0.02*0.75 -> 85500 | E30: =C30*0.02*0.25 -> 28500 | F30: =C30*0.005*0.7 -> 19950 | G30: =C30*0.005*0.3 -> 8550 | H30: =C30*0.03 -> 171000
A31: 25 | B31: Trần Thuận Châu | C31: 5700000 | D31: =C31*0.02*0.75 -> 85500 | E31: =C31*0.02*0.25 -> 28500 | F31: =C31*0.005*0.7 -> 19950 | G31: =C31*0.005*0.3 -> 8550 | H31: =C31*0.03 -> 171000 | I31: X
A32: 26 | B32: Phạm Tuấn Anh | C32: 5700000 | D32: =C32*0.02*0.75 -> 85500 | E32: =C32*0.02*0.25 -> 28500 | F32: =C32*0.005*0.7 -> 19950 | G32: =C32*0.005*0.3 -> 8550 | H32: =C32*0.03 -> 171000
A33: 27 | B33: Nguyễn Bá Quân | C33: 5700000 | D33: =C33*0.02*0.75 -> 85500 | E33: =C33*0.02*0.25 -> 28500 | F33: =C33*0.005*0.7 -> 19950 | G33: =C33*0.005*0.3 -> 8550 | H33: =C33*0.03 -> 171000
A34: 28 | B34: Sử Ngọc Quế | C34: 5700000 | D34: =C34*0.02*0.75 -> 85500 | E34: =C34*0.02*0.25 -> 28500 | F34: =C34*0.005*0.7 -> 19950 | G34: =C34*0.005*0.3 -> 8550 | H34: =C34*0.03 -> 171000 | I34: X
A35: 29 | B35: Ngô Thị Tuyết | C35: 5700000 | D35: =C35*0.02*0.75 -> 85500 | E35: =C35*0.02*0.25 -> 28500 | F35: =C35*0.005*0.7 -> 19950 | G35: =C35*0.005*0.3 -> 8550 | H35: =C35*0.03 -> 171000 | I35: X
A36: 30 | B36: Nguyễn Trường Vũ | C36: 20000000 | D36: =C36*0.02*0.75 -> 300000 | E36: =C36*0.02*0.25 -> 100000 | F36: =C36*0.005*0.7 -> 70000 | G36: =C36*0.005*0.3 -> 30000 | H36: =C36*0.03 -> 600000 | J36: Noted
A37: 31 | B37: Lê Thị Thu Thảo | C37: 5700000 | D37: =C37*0.02*0.75 -> 85500 | E37: =C37*0.02*0.25 -> 28500 | F37: =C37*0.005*0.7 -> 19950 | G37: =C37*0.005*0.3 -> 8550 | H37: =C37*0.03 -> 171000 | I37: X
A38: 32 | B38: Lâm Nhật Quang | C38: 5700000 | D38: =C38*0.02*0.75 -> 85500 | E38: =C38*0.02*0.25 -> 28500 | F38: =C38*0.005*0.7 -> 19950 | G38: =C38*0.005*0.3 -> 8550 | H38: =C38*0.03 -> 171000
A39: 33 | B39: Bùi Xuân Mai Thảo | C39: 5700000 | D39: =C39*0.02*0.75 -> 85500 | E39: =C39*0.02*0.25 -> 28500 | F39: =C39*0.005*0.7 -> 19950 | G39: =C39*0.005*0.3 -> 8550 | H39: =C39*0.03 -> 171000 | I39: X
A40: 34 | B40: Nguyễn Quốc Cảnh | C40: 5700000 | D40: =C40*0.02*0.75 -> 85500 | E40: =C40*0.02*0.25 -> 28500 | F40: =C40*0.005*0.7 -> 19950 | G40: =C40*0.005*0.3 -> 8550 | H40: =C40*0.03 -> 171000
...

Sheet 032026
A1: Hung Phat Co., Ltd
J2: Theo quyết định số 61/QĐ-TLĐ ngày 29/07/2025
A3: Danh Sách Trích Nộp Phí Công Đoàn Tháng 03/2026 | J3: Thay đổi mức đóng đoàn phí hằng tháng là 0.5%
J4: bắt đầu có hiệu lực từ ngày 01/07/2025
A5: STT | B5: Họ & tên | C5: Mức lương đóng | D5: Trích đóng 2% | F5: Trích đóng 0.5% đoàn phí công đoàn | H5: Tổng cộng | J5: bắt đầu từ tháng 10 bỏ 9 mã số (2301, 2302, 2303, 2305, 2307, 2308, 2313, 2315, 2316)
D6: Công đoàn Cty giữ 75% | E6: Liên đoàn VN giữ 25% | F6: Công đoàn Cty giữ 70% | G6: Liên đoàn QTP giữ 30% | J6: V105 nghỉ thai sản
A7: 1 | B7: Trần Minh Thắng | C7: 5700000 | D7: =C7*0.02*0.75 -> 85500 | E7: =C7*0.02*0.25 -> 28500 | F7: =C7*0.005*0.7 -> 19950 | G7: =C7*0.005*0.3 -> 8550 | H7: =C7*0.03 -> 171000 | J7: Thêm 1518
A8: 2 | B8: Lê Hoàng Sỹ | C8: 5700000 | D8: =C8*0.02*0.75 -> 85500 | E8: =C8*0.02*0.25 -> 28500 | F8: =C8*0.005*0.7 -> 19950 | G8: =C8*0.005*0.3 -> 8550 | H8: =C8*0.03 -> 171000
A9: 3 | B9: Dương Hồng Loan | C9: 5700000 | D9: =C9*0.02*0.75 -> 85500 | E9: =C9*0.02*0.25 -> 28500 | F9: =C9*0.005*0.7 -> 19950 | G9: =C9*0.005*0.3 -> 8550 | H9: =C9*0.03 -> 171000
A10: 4 | B10: Lê Chí Thân | C10: 5700000 | D10: =C10*0.02*0.75 -> 85500 | E10: =C10*0.02*0.25 -> 28500 | F10: =C10*0.005*0.7 -> 19950 | G10: =C10*0.005*0.3 -> 8550 | H10: =C10*0.03 -> 171000
A11: 5 | B11: Nguyễn Văn Hây | C11: 5700000 | D11: =C11*0.02*0.75 -> 85500 | E11: =C11*0.02*0.25 -> 28500 | F11: =C11*0.005*0.7 -> 19950 | G11: =C11*0.005*0.3 -> 8550 | H11: =C11*0.03 -> 171000
A12: 6 | B12: Võ Huy Phong | C12: 5700000 | D12: =C12*0.02*0.75 -> 85500 | E12: =C12*0.02*0.25 -> 28500 | F12: =C12*0.005*0.7 -> 19950 | G12: =C12*0.005*0.3 -> 8550 | H12: =C12*0.03 -> 171000
A13: 7 | B13: Nguyễn Bá Thành | C13: 5700000 | D13: =C13*0.02*0.75 -> 85500 | E13: =C13*0.02*0.25 -> 28500 | F13: =C13*0.005*0.7 -> 19950 | G13: =C13*0.005*0.3 -> 8550 | H13: =C13*0.03 -> 171000
A14: 8 | B14: Vòng Và Tuấn | C14: 5700000 | D14: =C14*0.02*0.75 -> 85500 | E14: =C14*0.02*0.25 -> 28500 | F14: =C14*0.005*0.7 -> 19950 | G14: =C14*0.005*0.3 -> 8550 | H14: =C14*0.03 -> 171000
A15: 9 | B15: Nguyễn Nguyên Hùng | C15: 5700000 | D15: =C15*0.02*0.75 -> 85500 | E15: =C15*0.02*0.25 -> 28500 | F15: =C15*0.005*0.7 -> 19950 | G15: =C15*0.005*0.3 -> 8550 | H15: =C15*0.03 -> 171000
A16: 10 | B16: Trần Thị Ngọc Dung | C16: 5700000 | D16: =C16*0.02*0.75 -> 85500 | E16: =C16*0.02*0.25 -> 28500 | F16: =C16*0.005*0.7 -> 19950 | G16: =C16*0.005*0.3 -> 8550 | H16: =C16*0.03 -> 171000
A17: 11 | B17: Cao Đình Dương | C17: 5700000 | D17: =C17*0.02*0.75 -> 85500 | E17: =C17*0.02*0.25 -> 28500 | F17: =C17*0.005*0.7 -> 19950 | G17: =C17*0.005*0.3 -> 8550 | H17: =C17*0.03 -> 171000
A18: 12 | B18: Thái Trung Dũng | C18: 5700000 | D18: =C18*0.02*0.75 -> 85500 | E18: =C18*0.02*0.25 -> 28500 | F18: =C18*0.005*0.7 -> 19950 | G18: =C18*0.005*0.3 -> 8550 | H18: =C18*0.03 -> 171000
A19: 13 | B19: Trần Văn Hiếu | C19: 5700000 | D19: =C19*0.02*0.75 -> 85500 | E19: =C19*0.02*0.25 -> 28500 | F19: =C19*0.005*0.7 -> 19950 | G19: =C19*0.005*0.3 -> 8550 | H19: =C19*0.03 -> 171000
... A33: 27 | B33: Nguyễn Bá Quân | C33: 5700000 | D33: =C33*0.02*0.75 -> 85500 | E33: =C33*0.02*0.25 -> 28500 | F33: =C33*0.005*0.7 -> 19950 | G33: =C33*0.005*0.3 -> 8550 | H33: =C33*0.03 -> 171000
A34: 28 | B34: Sử Ngọc Quế | C34: 0 | D34: =C34*0.02*0.75 -> 0 | E34: =C34*0.02*0.25 -> 0 | F34: =C34*0.005*0.7 -> 0 | G34: =C34*0.005*0.3 -> 0 | H34: =C34*0.03 -> 0 | I34: Nghỉ thai sản
A35: 29 | B35: Ngô Thị Tuyết | C35: 5700000 | D35: =C35*0.02*0.75 -> 85500 | E35: =C35*0.02*0.25 -> 28500 | F35: =C35*0.005*0.7 -> 19950 | G35: =C35*0.005*0.3 -> 8550 | H35: =C35*0.03 -> 171000
A36: 30 | B36: Nguyễn Trường Vũ | C36: 20000000 | D36: =C36*0.02*0.75 -> 300000 | E36: =C36*0.02*0.25 -> 100000 | F36: =C36*0.005*0.7 -> 70000 | G36: =C36*0.005*0.3 -> 30000 | H36: =C36*0.03 -> 600000
A37: 31 | B37: Lê Thị Thu Thảo | C37: 5700000 | D37: =C37*0.02*0.75 -> 85500 | E37: =C37*0.02*0.25 -> 28500 | F37: =C37*0.005*0.7 -> 19950 | G37: =C37*0.005*0.3 -> 8550 | H37: =C37*0.03 -> 171000
A38: 32 | B38: Lâm Nhật Quang | C38: 5700000 | D38: =C38*0.02*0.75 -> 85500 | E38: =C38*0.02*0.25 -> 28500 | F38: =C38*0.005*0.7 -> 19950 | G38: =C38*0.005*0.3 -> 8550 | H38: =C38*0.03 -> 171000
A39: 33 | B39: Bùi Xuân Mai Thảo | C39: 5700000 | D39: =C39*0.02*0.75 -> 85500 | E39: =C39*0.02*0.25 -> 28500 | F39: =C39*0.005*0.7 -> 19950 | G39: =C39*0.005*0.3 -> 8550 | H39: =C39*0.03 -> 171000
A40: 34 | B40: Nguyễn Quốc Cảnh | C40: 5700000 | D40: =C40*0.02*0.75 -> 85500 | E40: =C40*0.02*0.25 -> 28500 | F40: =C40*0.005*0.7 -> 19950 | G40: =C40*0.005*0.3 -> 8550 | H40: =C40*0.03 -> 171000
A41: 35 | B41: Huỳnh Thế Sơn | C41: 5700000 | D41: =C41*0.02*0.75 -> 85500 | E41: =C41*0.02*0.25 -> 28500 | F41: =C41*0.005*0.7 -> 19950 | G41: =C41*0.005*0.3 -> 8550 | H41: =C41*0.03 -> 171000
A42: 36 | B42: Nguyễn Thị Kỳ Duyên | C42: 5700000 | D42: =C42*0.02*0.75 -> 85500 | E42: =C42*0.02*0.25 -> 28500 | F42: =C42*0.005*0.7 -> 19950 | G42: =C42*0.005*0.3 -> 8550 | H42: =C42*0.03 -> 171000
A43: 37 | B43: Nguyễn Thị Mai Thi | C43: 5700000 | D43: =C43*0.02*0.75 -> 85500 | E43: =C43*0.02*0.25 -> 28500 | F43: =C43*0.005*0.7 -> 19950 | G43: =C43*0.005*0.3 -> 8550 | H43: =C43*0.03 -> 171000
A44: 38 | B44: Nông Hoàng Phát | C44: 5700000 | D44: =C44*0.02*0.75 -> 85500 | E44: =C44*0.02*0.25 -> 28500 | F44: =C44*0.005*0.7 -> 19950 | G44: =C44*0.005*0.3 -> 8550 | H44: =C44*0.03 -> 171000
A45: 39 | B45: Lê Thị Nhã Mi | C45: 0 | D45: =C45*0.02*0.75 -> 0 | E45: =C45*0.02*0.25 -> 0 | F45: =C45*0.005*0.7 -> 0 | G45: =C45*0.005*0.3 -> 0 | H45: =C45*0.03 -> 0 | I45: Nghỉ thai sản
A46: 40 | B46: Nguyễn Thị Cẩm Ly | C46: 5700000 | D46: =C46*0.02*0.75 -> 85500 | E46: =C46*0.02*0.25 -> 28500 | F46: =C46*0.005*0.7 -> 19950 | G46: =C46*0.005*0.3 -> 8550 | H46: =C46*0.03 -> 171000
A47: 41 | B47: Lê Thị Hiếu Thư | C47: 5700000 | D47: =C47*0.02*0.75 -> 85500 | E47: =C47*0.02*0.25 -> 28500 | F47: =C47*0.005*0.7 -> 19950 | G47: =C47*0.005*0.3 -> 8550 | H47: =C47*0.03 -> 171000
A48: 42 | B48: Bùi Thị Kim Chi | C48: 5700000 | D48: =C48*0.02*0.75 -> 85500 | E48: =C48*0.02*0.25 -> 28500 | F48: =C48*0.005*0.7 -> 19950 | G48: =C48*0.005*0.3 -> 8550 | H48: =C48*0.03 -> 171000
A49: 43 | B49: Ngô Thị Ngọc Dung | C49: 5700000 | D49: =C49*0.02*0.75 -> 85500 | E49: =C49*0.02*0.25 -> 28500 | F49: =C49*0.005*0.7 -> 19950 | G49: =C49*0.005*0.3 -> 8550 | H49: =C49*0.03 -> 171000
B51: Tổng | C51: =SUM(C7:C50) -> 256910000 | D51: =SUM(D7:D50) -> 3853650 | E51: =SUM(E7:E50) -> 1284550 | F51: =SUM(F7:F50) -> 899185 | G51: =SUM(G7:G50) -> 385365 | H51: =SUM(H7:H50) -> 7707300
E53: Ngày 01 tháng 03 năm 2026
E54: Người lập
E59: Nguyễn Thị Cẩm Ly

Sheet 042026
A1: Hung Phat Co., Ltd
J2: Theo quyết định số 61/QĐ-TLĐ ngày 29/07/2025
A3: Danh Sách Trích Nộp Phí Công Đoàn Tháng 04/2026 | J3: Thay đổi mức đóng đoàn phí hằng tháng là 0.5%
J4: bắt đầu có hiệu lực từ ngày 01/07/2025
A5: STT | B5: Họ & tên | C5: Mức lương đóng | D5: Trích đóng 2% | F5: Trích đóng 0.5% đoàn phí công đoàn | H5: Tổng cộng | J5: bắt đầu từ tháng 10 bỏ 9 mã số (2301, 2302, 2303, 2305, 2307, 2308, 2313, 2315, 2316)
D6: Công đoàn Cty giữ 75% | E6: Liên đoàn VN giữ 25% | F6: Công đoàn Cty giữ 70% | G6: Liên đoàn QTP giữ 30% | J6: V105 nghỉ thai sản
A7: 1 | B7: Trần Minh Thắng | C7: 5700000 | D7: =C7*0.02*0.75 -> 85500 | E7: =C7*0.02*0.25 -> 28500 | F7: =C7*0.005*0.7 -> 19950 | G7: =C7*0.005*0.3 -> 8550 | H7: =C7*0.03 -> 171000 | J7: Thêm 1518
A8: 2 | B8: Lê Hoàng Sỹ | C8: 5700000 | D8: =C8*0.02*0.75 -> 85500 | E8: =C8*0.02*0.25 -> 28500 | F8: =C8*0.005*0.7 -> 19950 | G8: =C8*0.005*0.3 -> 8550 | H8: =C8*0.03 -> 171000
A9: 3 | B9: Dương Hồng Loan | C9: 5700000 | D9: =C9*0.02*0.75 -> 85500 | E9: =C9*0.02*0.25 -> 28500 | F9: =C9*0.005*0.7 -> 19950 | G9: =C9*0.005*0.3 -> 8550 | H9: =C9*0.03 -> 171000
A10: 4 | B10: Lê Chí Thân | C10: 5700000 | D10: =C10*0.02*0.75 -> 85500 | E10: =C10*0.02*0.25 -> 28500 | F10: =C10*0.005*0.7 -> 19950 | G10: =C10*0.005*0.3 -> 8550 | H10: =C10*0.03 -> 171000
A11: 5 | B11: Nguyễn Văn Hây | C11: 5700000 | D11: =C11*0.02*0.75 -> 85500 | E11: =C11*0.02*0.25 -> 28500 | F11: =C11*0.005*0.7 -> 19950 | G11: =C11*0.005*0.3 -> 8550 | H11: =C11*0.03 -> 171000
A12: 6 | B12: Võ Huy Phong | C12: 5700000 | D12: =C12*0.02*0.75 -> 85500 | E12: =C12*0.02*0.25 -> 28500 | F12: =C12*0.005*0.7 -> 19950 | G12: =C12*0.005*0.3 -> 8550 | H12: =C12*0.03 -> 171000
A13: 7 | B13: Nguyễn Bá Thành | C13: 5700000 | D13: =C13*0.02*0.75 -> 85500 | E13: =C13*0.02*0.25 -> 28500 | F13: =C13*0.005*0.7 -> 19950 | G13: =C13*0.005*0.3 -> 8550 | H13: =C13*0.03 -> 171000
A14: 8 | B14: Vòng Và Tuấn | C14: 5700000 | D14: =C14*0.02*0.75 -> 85500 | E14: =C14*0.02*0.25 -> 28500 | F14: =C14*0.005*0.7 -> 19950 | G14: =C14*0.005*0.3 -> 8550 | H14: =C14*0.03 -> 171000
A15: 9 | B15: Nguyễn Nguyên Hùng | C15: 5700000 | D15: =C15*0.02*0.75 -> 85500 | E15: =C15*0.02*0.25 -> 28500 | F15: =C15*0.005*0.7 -> 19950 | G15: =C15*0.005*0.3 -> 8550 | H15: =C15*0.03 -> 171000
A16: 10 | B16: Trần Thị Ngọc Dung | C16: 5700000 | D16: =C16*0.02*0.75 -> 85500 | E16: =C16*0.02*0.25 -> 28500 | F16: =C16*0.005*0.7 -> 19950 | G16: =C16*0.005*0.3 -> 8550 | H16: =C16*0.03 -> 171000
A17: 11 | B17: Cao Đình Dương | C17: 5700000 | D17: =C17*0.02*0.75 -> 85500 | E17: =C17*0.02*0.25 -> 28500 | F17: =C17*0.005*0.7 -> 19950 | G17: =C17*0.005*0.3 -> 8550 | H17: =C17*0.03 -> 171000
A18: 12 | B18: Thái Trung Dũng | C18: 5700000 | D18: =C18*0.02*0.75 -> 85500 | E18: =C18*0.02*0.25 -> 28500 | F18: =C18*0.005*0.7 -> 19950 | G18: =C18*0.005*0.3 -> 8550 | H18: =C18*0.03 -> 171000
A19: 13 | B19: Trần Văn Hiếu | C19: 5700000 | D19: =C19*0.02*0.75 -> 85500 | E19: =C19*0.02*0.25 -> 28500 | F19: =C19*0.005*0.7 -> 19950 | G19: =C19*0.005*0.3 -> 8550 | H19: =C19*0.03 -> 171000
... A34: 28 | B34: Nguyễn Bá Quân | C34: 5700000 | D34: =C34*0.02*0.75 -> 85500 | E34: =C34*0.02*0.25 -> 28500 | F34: =C34*0.005*0.7 -> 19950 | G34: =C34*0.005*0.3 -> 8550 | H34: =C34*0.03 -> 171000
A35: 29 | B35: Sử Ngọc Quế | C35: 0 | D35: =C35*0.02*0.75 -> 0 | E35: =C35*0.02*0.25 -> 0 | F35: =C35*0.005*0.7 -> 0 | G35: =C35*0.005*0.3 -> 0 | H35: =C35*0.03 -> 0 | I35: Nghỉ thai sản
A36: 30 | B36: Ngô Thị Tuyết | C36: 5700000 | D36: =C36*0.02*0.75 -> 85500 | E36: =C36*0.02*0.25 -> 28500 | F36: =C36*0.005*0.7 -> 19950 | G36: =C36*0.005*0.3 -> 8550 | H36: =C36*0.03 -> 171000
A37: 31 | B37: Nguyễn Trường Vũ | C37: 20000000 | D37: =C37*0.02*0.75 -> 300000 | E37: =C37*0.02*0.25 -> 100000 | F37: =C37*0.005*0.7 -> 70000 | G37: =C37*0.005*0.3 -> 30000 | H37: =C37*0.03 -> 600000
A38: 32 | B38: Lê Thị Thu Thảo | C38: 5700000 | D38: =C38*0.02*0.75 -> 85500 | E38: =C38*0.02*0.25 -> 28500 | F38: =C38*0.005*0.7 -> 19950 | G38: =C38*0.005*0.3 -> 8550 | H38: =C38*0.03 -> 171000
A39: 33 | B39: Lâm Nhật Quang | C39: 5700000 | D39: =C39*0.02*0.75 -> 85500 | E39: =C39*0.02*0.25 -> 28500 | F39: =C39*0.005*0.7 -> 19950 | G39: =C39*0.005*0.3 -> 8550 | H39: =C39*0.03 -> 171000
A40: 34 | B40: Bùi Xuân Mai Thảo | C40: 5700000 | D40: =C40*0.02*0.75 -> 85500 | E40: =C40*0.02*0.25 -> 28500 | F40: =C40*0.005*0.7 -> 19950 | G40: =C40*0.005*0.3 -> 8550 | H40: =C40*0.03 -> 171000
A41: 35 | B41: Nguyễn Quốc Cảnh | C41: 5700000 | D41: =C41*0.02*0.75 -> 85500 | E41: =C41*0.02*0.25 -> 28500 | F41: =C41*0.005*0.7 -> 19950 | G41: =C41*0.005*0.3 -> 8550 | H41: =C41*0.03 -> 171000
A42: 36 | B42: Huỳnh Thế Sơn | C42: 5700000 | D42: =C42*0.02*0.75 -> 85500 | E42: =C42*0.02*0.25 -> 28500 | F42: =C42*0.005*0.7 -> 19950 | G42: =C42*0.005*0.3 -> 8550 | H42: =C42*0.03 -> 171000
A43: 37 | B43: Nguyễn Thị Kỳ Duyên | C43: 5700000 | D43: =C43*0.02*0.75 -> 85500 | E43: =C43*0.02*0.25 -> 28500 | F43: =C43*0.005*0.7 -> 19950 | G43: =C43*0.005*0.3 -> 8550 | H43: =C43*0.03 -> 171000
A44: 38 | B44: Nguyễn Thị Mai Thi | C44: 5700000 | D44: =C44*0.02*0.75 -> 85500 | E44: =C44*0.02*0.25 -> 28500 | F44: =C44*0.005*0.7 -> 19950 | G44: =C44*0.005*0.3 -> 8550 | H44: =C44*0.03 -> 171000
A45: 39 | B45: Nông Hoàng Phát | C45: 5700000 | D45: =C45*0.02*0.75 -> 85500 | E45: =C45*0.02*0.25 -> 28500 | F45: =C45*0.005*0.7 -> 19950 | G45: =C45*0.005*0.3 -> 8550 | H45: =C45*0.03 -> 171000
A46: 40 | B46: Lê Thị Nhã Mi | C46: 0 | D46: =C46*0.02*0.75 -> 0 | E46: =C46*0.02*0.25 -> 0 | F46: =C46*0.005*0.7 -> 0 | G46: =C46*0.005*0.3 -> 0 | H46: =C46*0.03 -> 0 | I46: Nghỉ không lương
A47: 41 | B47: Nguyễn Thị Cẩm Ly | C47: 5700000 | D47: =C47*0.02*0.75 -> 85500 | E47: =C47*0.02*0.25 -> 28500 | F47: =C47*0.005*0.7 -> 19950 | G47: =C47*0.005*0.3 -> 8550 | H47: =C47*0.03 -> 171000
A48: 42 | B48: Lê Thị Hiếu Thư | C48: 5700000 | D48: =C48*0.02*0.75 -> 85500 | E48: =C48*0.02*0.25 -> 28500 | F48: =C48*0.005*0.7 -> 19950 | G48: =C48*0.005*0.3 -> 8550 | H48: =C48*0.03 -> 171000
A49: 43 | B49: Bùi Thị Kim Chi | C49: 5700000 | D49: =C49*0.02*0.75 -> 85500 | E49: =C49*0.02*0.25 -> 28500 | F49: =C49*0.005*0.7 -> 19950 | G49: =C49*0.005*0.3 -> 8550 | H49: =C49*0.03 -> 171000
A50: 44 | B50: Ngô Thị Ngọc Dung | C50: 5700000 | D50: =C50*0.02*0.75 -> 85500 | E50: =C50*0.02*0.25 -> 28500 | F50: =C50*0.005*0.7 -> 19950 | G50: =C50*0.005*0.3 -> 8550 | H50: =C50*0.03 -> 171000
B52: Tổng | C52: =SUM(C7:C51) -> 262610000 | D52: =SUM(D7:D51) -> 3939150 | E52: =SUM(E7:E51) -> 1313050 | F52: =SUM(F7:F51) -> 919135 | G52: =SUM(G7:G51) -> 393915 | H52: =SUM(H7:H51) -> 7878300
E54: Ngày 01 tháng 04 năm 2026
E55: Người lập
E60: Nguyễn Thị Cẩm Ly

Sheet 052026
A1: Hung Phat Co., Ltd
J2: Theo quyết định số 61/QĐ-TLĐ ngày 29/07/2025
A3: Danh Sách Trích Nộp Phí Công Đoàn Tháng 05/2026 | J3: Thay đổi mức đóng đoàn phí hằng tháng là 0.5%
J4: bắt đầu có hiệu lực từ ngày 01/07/2025
A5: STT | B5: Họ & tên | C5: Mức lương đóng | D5: Trích đóng 2% | F5: Trích đóng 0.5% đoàn phí công đoàn | H5: Tổng cộng | J5: bắt đầu từ tháng 10 bỏ 9 mã số (2301, 2302, 2303, 2305, 2307, 2308, 2313, 2315, 2316)
D6: Công đoàn Cty giữ 75% | E6: Liên đoàn VN giữ 25% | F6: Công đoàn Cty giữ 70% | G6: Liên đoàn QTP giữ 30% | J6: V105 nghỉ thai sản
A7: 1 | B7: Trần Minh Thắng | C7: 5700000 | D7: =C7*0.02*0.75 -> 85500 | E7: =C7*0.02*0.25 -> 28500 | F7: =C7*0.005*0.7 -> 19950 | G7: =C7*0.005*0.3 -> 8550 | H7: =C7*0.03 -> 171000 | J7: Thêm 1518
A8: 2 | B8: Lê Hoàng Sỹ | C8: 5700000 | D8: =C8*0.02*0.75 -> 85500 | E8: =C8*0.02*0.25 -> 28500 | F8: =C8*0.005*0.7 -> 19950 | G8: =C8*0.005*0.3 -> 8550 | H8: =C8*0.03 -> 171000
A9: 3 | B9: Dương Hồng Loan | C9: 5700000 | D9: =C9*0.02*0.75 -> 85500 | E9: =C9*0.02*0.25 -> 28500 | F9: =C9*0.005*0.7 -> 19950 | G9: =C9*0.005*0.3 -> 8550 | H9: =C9*0.03 -> 171000
A10: 4 | B10: Lê Chí Thân | C10: 5700000 | D10: =C10*0.02*0.75 -> 85500 | E10: =C10*0.02*0.25 -> 28500 | F10: =C10*0.005*0.7 -> 19950 | G10: =C10*0.005*0.3 -> 8550 | H10: =C10*0.03 -> 171000
A11: 5 | B11: Nguyễn Văn Hây | C11: 5700000 | D11: =C11*0.02*0.75 -> 85500 | E11: =C11*0.02*0.25 -> 28500 | F11: =C11*0.005*0.7 -> 19950 | G11: =C11*0.005*0.3 -> 8550 | H11: =C11*0.03 -> 171000
A12: 6 | B12: Võ Huy Phong | C12: 5700000 | D12: =C12*0.02*0.75 -> 85500 | E12: =C12*0.02*0.25 -> 28500 | F12: =C12*0.005*0.7 -> 19950 | G12: =C12*0.005*0.3 -> 8550 | H12: =C12*0.03 -> 171000
A13: 7 | B13: Nguyễn Bá Thành | C13: 5700000 | D13: =C13*0.02*0.75 -> 85500 | E13: =C13*0.02*0.25 -> 28500 | F13: =C13*0.005*0.7 -> 19950 | G13: =C13*0.005*0.3 -> 8550 | H13: =C13*0.03 -> 171000
A14: 8 | B14: Vòng Và Tuấn | C14: 5700000 | D14: =C14*0.02*0.75 -> 85500 | E14: =C14*0.02*0.25 -> 28500 | F14: =C14*0.005*0.7 -> 19950 | G14: =C14*0.005*0.3 -> 8550 | H14: =C14*0.03 -> 171000
A15: 9 | B15: Nguyễn Nguyên Hùng | C15: 5700000 | D15: =C15*0.02*0.75 -> 85500 | E15: =C15*0.02*0.25 -> 28500 | F15: =C15*0.005*0.7 -> 19950 | G15: =C15*0.005*0.3 -> 8550 | H15: =C15*0.03 -> 171000
A16: 10 | B16: Trần Thị Ngọc Dung | C16: 5700000 | D16: =C16*0.02*0.75 -> 85500 | E16: =C16*0.02*0.25 -> 28500 | F16: =C16*0.005*0.7 -> 19950 | G16: =C16*0.005*0.3 -> 8550 | H16: =C16*0.03 -> 171000
A17: 11 | B17: Cao Đình Dương | C17: 5700000 | D17: =C17*0.02*0.75 -> 85500 | E17: =C17*0.02*0.25 -> 28500 | F17: =C17*0.005*0.7 -> 19950 | G17: =C17*0.005*0.3 -> 8550 | H17: =C17*0.03 -> 171000
A18: 12 | B18: Thái Trung Dũng | C18: 5700000 | D18: =C18*0.02*0.75 -> 85500 | E18: =C18*0.02*0.25 -> 28500 | F18: =C18*0.005*0.7 -> 19950 | G18: =C18*0.005*0.3 -> 8550 | H18: =C18*0.03 -> 171000
A19: 13 | B19: Trần Văn Hiếu | C19: 5700000 | D19: =C19*0.02*0.75 -> 85500 | E19: =C19*0.02*0.25 -> 28500 | F19: =C19*0.005*0.7 -> 19950 | G19: =C19*0.005*0.3 -> 8550 | H19: =C19*0.03 -> 171000
... A34: 28 | B34: Nguyễn Bá Quân | C34: 5700000 | D34: =C34*0.02*0.75 -> 85500 | E34: =C34*0.02*0.25 -> 28500 | F34: =C34*0.005*0.7 -> 19950 | G34: =C34*0.005*0.3 -> 8550 | H34: =C34*0.03 -> 171000
A35: 29 | B35: Sử Ngọc Quế | C35: 0 | D35: =C35*0.02*0.75 -> 0 | E35: =C35*0.02*0.25 -> 0 | F35: =C35*0.005*0.7 -> 0 | G35: =C35*0.005*0.3 -> 0 | H35: =C35*0.03 -> 0 | I35: Nghỉ thai sản
A36: 30 | B36: Ngô Thị Tuyết | C36: 5700000 | D36: =C36*0.02*0.75 -> 85500 | E36: =C36*0.02*0.25 -> 28500 | F36: =C36*0.005*0.7 -> 19950 | G36: =C36*0.005*0.3 -> 8550 | H36: =C36*0.03 -> 171000
A37: 31 | B37: Nguyễn Trường Vũ | C37: 20000000 | D37: =C37*0.02*0.75 -> 300000 | E37: =C37*0.02*0.25 -> 100000 | F37: =C37*0.005*0.7 -> 70000 | G37: =C37*0.005*0.3 -> 30000 | H37: =C37*0.03 -> 600000
A38: 32 | B38: Lê Thị Thu Thảo | C38: 5700000 | D38: =C38*0.02*0.75 -> 85500 | E38: =C38*0.02*0.25 -> 28500 | F38: =C38*0.005*0.7 -> 19950 | G38: =C38*0.005*0.3 -> 8550 | H38: =C38*0.03 -> 171000
A39: 33 | B39: Lâm Nhật Quang | C39: 5700000 | D39: =C39*0.02*0.75 -> 85500 | E39: =C39*0.02*0.25 -> 28500 | F39: =C39*0.005*0.7 -> 19950 | G39: =C39*0.005*0.3 -> 8550 | H39: =C39*0.03 -> 171000
A40: 34 | B40: Bùi Xuân Mai Thảo | C40: 5700000 | D40: =C40*0.02*0.75 -> 85500 | E40: =C40*0.02*0.25 -> 28500 | F40: =C40*0.005*0.7 -> 19950 | G40: =C40*0.005*0.3 -> 8550 | H40: =C40*0.03 -> 171000
A41: 35 | B41: Nguyễn Quốc Cảnh | C41: 5700000 | D41: =C41*0.02*0.75 -> 85500 | E41: =C41*0.02*0.25 -> 28500 | F41: =C41*0.005*0.7 -> 19950 | G41: =C41*0.005*0.3 -> 8550 | H41: =C41*0.03 -> 171000
A42: 36 | B42: Huỳnh Thế Sơn | C42: 5700000 | D42: =C42*0.02*0.75 -> 85500 | E42: =C42*0.02*0.25 -> 28500 | F42: =C42*0.005*0.7 -> 19950 | G42: =C42*0.005*0.3 -> 8550 | H42: =C42*0.03 -> 171000
A43: 37 | B43: Nguyễn Thị Kỳ Duyên | C43: 5700000 | D43: =C43*0.02*0.75 -> 85500 | E43: =C43*0.02*0.25 -> 28500 | F43: =C43*0.005*0.7 -> 19950 | G43: =C43*0.005*0.3 -> 8550 | H43: =C43*0.03 -> 171000
A44: 38 | B44: Nguyễn Thị Mai Thi | C44: 5700000 | D44: =C44*0.02*0.75 -> 85500 | E44: =C44*0.02*0.25 -> 28500 | F44: =C44*0.005*0.7 -> 19950 | G44: =C44*0.005*0.3 -> 8550 | H44: =C44*0.03 -> 171000
A45: 39 | B45: Nông Hoàng Phát | C45: 5700000 | D45: =C45*0.02*0.75 -> 85500 | E45: =C45*0.02*0.25 -> 28500 | F45: =C45*0.005*0.7 -> 19950 | G45: =C45*0.005*0.3 -> 8550 | H45: =C45*0.03 -> 171000
A46: 40 | B46: Lê Thị Nhã Mi | C46: 5700000 | D46: =C46*0.02*0.75 -> 85500 | E46: =C46*0.02*0.25 -> 28500 | F46: =C46*0.005*0.7 -> 19950 | G46: =C46*0.005*0.3 -> 8550 | H46: =C46*0.03 -> 171000 | I46: Đã đi làm lại
A47: 41 | B47: Nguyễn Thị Cẩm Ly | C47: 5700000 | D47: =C47*0.02*0.75 -> 85500 | E47: =C47*0.02*0.25 -> 28500 | F47: =C47*0.005*0.7 -> 19950 | G47: =C47*0.005*0.3 -> 8550 | H47: =C47*0.03 -> 171000
A48: 42 | B48: Lê Thị Hiếu Thư | C48: 5700000 | D48: =C48*0.02*0.75 -> 85500 | E48: =C48*0.02*0.25 -> 28500 | F48: =C48*0.005*0.7 -> 19950 | G48: =C48*0.005*0.3 -> 8550 | H48: =C48*0.03 -> 171000
A49: 43 | B49: Bùi Thị Kim Chi | C49: 5700000 | D49: =C49*0.02*0.75 -> 85500 | E49: =C49*0.02*0.25 -> 28500 | F49: =C49*0.005*0.7 -> 19950 | G49: =C49*0.005*0.3 -> 8550 | H49: =C49*0.03 -> 171000
A50: 44 | B50: Ngô Thị Ngọc Dung | C50: 5700000 | D50: =C50*0.02*0.75 -> 85500 | E50: =C50*0.02*0.25 -> 28500 | F50: =C50*0.005*0.7 -> 19950 | G50: =C50*0.005*0.3 -> 8550 | H50: =C50*0.03 -> 171000
B52: Tổng | C52: =SUM(C7:C51) -> 268310000 | D52: =SUM(D7:D51) -> 4024650 | E52: =SUM(E7:E51) -> 1341550 | F52: =SUM(F7:F51) -> 939085 | G52: =SUM(G7:G51) -> 402465 | H52: =SUM(H7:H51) -> 8049300
D53: =+D52+E52 -> 5366200
E54: Ngày 01 tháng 05 năm 2026
E55: Người lập
...

Sheet 062026
A1: Hung Phat Co., Ltd
J2: Theo quyết định số 61/QĐ-TLĐ ngày 29/07/2025
A3: Danh Sách Trích Nộp Phí Công Đoàn Tháng 06/2026 | J3: Thay đổi mức đóng đoàn phí hằng tháng là 0.5%
J4: bắt đầu có hiệu lực từ ngày 01/07/2025
A5: STT | B5: Họ & tên | C5: Mức lương đóng | D5: Trích đóng 2% | F5: Trích đóng 0.5% đoàn phí công đoàn | H5: Tổng cộng | J5: bắt đầu từ tháng 10 bỏ 9 mã số (2301, 2302, 2303, 2305, 2307, 2308, 2313, 2315, 2316)
D6: Công đoàn Cty giữ 75% | E6: Liên đoàn VN giữ 25% | F6: Công đoàn Cty giữ 70% | G6: Liên đoàn QTP giữ 30%
A7: 1 | B7: Trần Minh Thắng | C7: 5700000 | D7: =C7*0.02*0.75 -> 85500 | E7: =C7*0.02*0.25 -> 28500 | F7: =C7*0.005*0.7 -> 19950 | G7: =C7*0.005*0.3 -> 8550 | H7: =C7*0.03 -> 171000
A8: 2 | B8: Lê Hoàng Sỹ | C8: 5700000 | D8: =C8*0.02*0.75 -> 85500 | E8: =C8*0.02*0.25 -> 28500 | F8: =C8*0.005*0.7 -> 19950 | G8: =C8*0.005*0.3 -> 8550 | H8: =C8*0.03 -> 171000
A9: 3 | B9: Dương Hồng Loan | C9: 5700000 | D9: =C9*0.02*0.75 -> 85500 | E9: =C9*0.02*0.25 -> 28500 | F9: =C9*0.005*0.7 -> 19950 | G9: =C9*0.005*0.3 -> 8550 | H9: =C9*0.03 -> 171000
A10: 4 | B10: Lê Chí Thân | C10: 5700000 | D10: =C10*0.02*0.75 -> 85500 | E10: =C10*0.02*0.25 -> 28500 | F10: =C10*0.005*0.7 -> 19950 | G10: =C10*0.005*0.3 -> 8550 | H10: =C10*0.03 -> 171000
A11: 5 | B11: Nguyễn Văn Hây | C11: 5700000 | D11: =C11*0.02*0.75 -> 85500 | E11: =C11*0.02*0.25 -> 28500 | F11: =C11*0.005*0.7 -> 19950 | G11: =C11*0.005*0.3 -> 8550 | H11: =C11*0.03 -> 171000
A12: 6 | B12: Võ Huy Phong | C12: 5700000 | D12: =C12*0.02*0.75 -> 85500 | E12: =C12*0.02*0.25 -> 28500 | F12: =C12*0.005*0.7 -> 19950 | G12: =C12*0.005*0.3 -> 8550 | H12: =C12*0.03 -> 171000
A13: 7 | B13: Nguyễn Bá Thành | C13: 5700000 | D13: =C13*0.02*0.75 -> 85500 | E13: =C13*0.02*0.25 -> 28500 | F13: =C13*0.005*0.7 -> 19950 | G13: =C13*0.005*0.3 -> 8550 | H13: =C13*0.03 -> 171000
A14: 8 | B14: Vòng Và Tuấn | C14: 5700000 | D14: =C14*0.02*0.75 -> 85500 | E14: =C14*0.02*0.25 -> 28500 | F14: =C14*0.005*0.7 -> 19950 | G14: =C14*0.005*0.3 -> 8550 | H14: =C14*0.03 -> 171000
A15: 9 | B15: Nguyễn Nguyên Hùng | C15: 5700000 | D15: =C15*0.02*0.75 -> 85500 | E15: =C15*0.02*0.25 -> 28500 | F15: =C15*0.005*0.7 -> 19950 | G15: =C15*0.005*0.3 -> 8550 | H15: =C15*0.03 -> 171000
A16: 10 | B16: Trần Thị Ngọc Dung | C16: 5700000 | D16: =C16*0.02*0.75 -> 85500 | E16: =C16*0.02*0.25 -> 28500 | F16: =C16*0.005*0.7 -> 19950 | G16: =C16*0.005*0.3 -> 8550 | H16: =C16*0.03 -> 171000
A17: 11 | B17: Cao Đình Dương | C17: 5700000 | D17: =C17*0.02*0.75 -> 85500 | E17: =C17*0.02*0.25 -> 28500 | F17: =C17*0.005*0.7 -> 19950 | G17: =C17*0.005*0.3 -> 8550 | H17: =C17*0.03 -> 171000
A18: 12 | B18: Thái Trung Dũng | C18: 5700000 | D18: =C18*0.02*0.75 -> 85500 | E18: =C18*0.02*0.25 -> 28500 | F18: =C18*0.005*0.7 -> 19950 | G18: =C18*0.005*0.3 -> 8550 | H18: =C18*0.03 -> 171000
... A34: 28 | B34: Nguyễn Bá Quân | C34: 5700000 | D34: =C34*0.02*0.75 -> 85500 | E34: =C34*0.02*0.25 -> 28500 | F34: =C34*0.005*0.7 -> 19950 | G34: =C34*0.005*0.3 -> 8550 | H34: =C34*0.03 -> 171000
A35: 29 | B35: Sử Ngọc Quế | C35: 0 | D35: =C35*0.02*0.75 -> 0 | E35: =C35*0.02*0.25 -> 0 | F35: =C35*0.005*0.7 -> 0 | G35: =C35*0.005*0.3 -> 0 | H35: =C35*0.03 -> 0 | I35: Nghỉ thai sản
A36: 30 | B36: Ngô Thị Tuyết | C36: 5700000 | D36: =C36*0.02*0.75 -> 85500 | E36: =C36*0.02*0.25 -> 28500 | F36: =C36*0.005*0.7 -> 19950 | G36: =C36*0.005*0.3 -> 8550 | H36: =C36*0.03 -> 171000
A37: 31 | B37: Nguyễn Trường Vũ | C37: 20000000 | D37: =C37*0.02*0.75 -> 300000 | E37: =C37*0.02*0.25 -> 100000 | F37: =C37*0.005*0.7 -> 70000 | G37: =C37*0.005*0.3 -> 30000 | H37: =C37*0.03 -> 600000
A38: 32 | B38: Lê Thị Thu Thảo | C38: 5700000 | D38: =C38*0.02*0.75 -> 85500 | E38: =C38*0.02*0.25 -> 28500 | F38: =C38*0.005*0.7 -> 19950 | G38: =C38*0.005*0.3 -> 8550 | H38: =C38*0.03 -> 171000
A39: 33 | B39: Lâm Nhật Quang | C39: 5700000 | D39: =C39*0.02*0.75 -> 85500 | E39: =C39*0.02*0.25 -> 28500 | F39: =C39*0.005*0.7 -> 19950 | G39: =C39*0.005*0.3 -> 8550 | H39: =C39*0.03 -> 171000
A40: 34 | B40: Bùi Xuân Mai Thảo | C40: 5700000 | D40: =C40*0.02*0.75 -> 85500 | E40: =C40*0.02*0.25 -> 28500 | F40: =C40*0.005*0.7 -> 19950 | G40: =C40*0.005*0.3 -> 8550 | H40: =C40*0.03 -> 171000
A41: 35 | B41: Nguyễn Quốc Cảnh | C41: 0 | D41: =C41*0.02*0.75 -> 0 | E41: =C41*0.02*0.25 -> 0 | F41: =C41*0.005*0.7 -> 0 | G41: =C41*0.005*0.3 -> 0 | H41: =C41*0.03 -> 0 | I41: Nghỉ việc
A42: 36 | B42: Huỳnh Thế Sơn | C42: 5700000 | D42: =C42*0.02*0.75 -> 85500 | E42: =C42*0.02*0.25 -> 28500 | F42: =C42*0.005*0.7 -> 19950 | G42: =C42*0.005*0.3 -> 8550 | H42: =C42*0.03 -> 171000
A43: 37 | B43: Nguyễn Thị Kỳ Duyên | C43: 5700000 | D43: =C43*0.02*0.75 -> 85500 | E43: =C43*0.02*0.25 -> 28500 | F43: =C43*0.005*0.7 -> 19950 | G43: =C43*0.005*0.3 -> 8550 | H43: =C43*0.03 -> 171000
A44: 38 | B44: Nguyễn Thị Mai Thi | C44: 5700000 | D44: =C44*0.02*0.75 -> 85500 | E44: =C44*0.02*0.25 -> 28500 | F44: =C44*0.005*0.7 -> 19950 | G44: =C44*0.005*0.3 -> 8550 | H44: =C44*0.03 -> 171000
A45: 39 | B45: Nông Hoàng Phát | C45: 5700000 | D45: =C45*0.02*0.75 -> 85500 | E45: =C45*0.02*0.25 -> 28500 | F45: =C45*0.005*0.7 -> 19950 | G45: =C45*0.005*0.3 -> 8550 | H45: =C45*0.03 -> 171000
A46: 40 | B46: Lê Thị Nhã Mi | C46: 5700000 | D46: =C46*0.02*0.75 -> 85500 | E46: =C46*0.02*0.25 -> 28500 | F46: =C46*0.005*0.7 -> 19950 | G46: =C46*0.005*0.3 -> 8550 | H46: =C46*0.03 -> 171000
A47: 41 | B47: Nguyễn Thị Cẩm Ly | C47: 5700000 | D47: =C47*0.02*0.75 -> 85500 | E47: =C47*0.02*0.25 -> 28500 | F47: =C47*0.005*0.7 -> 19950 | G47: =C47*0.005*0.3 -> 8550 | H47: =C47*0.03 -> 171000
A48: 42 | B48: Lê Thị Hiếu Thư | C48: 5700000 | D48: =C48*0.02*0.75 -> 85500 | E48: =C48*0.02*0.25 -> 28500 | F48: =C48*0.005*0.7 -> 19950 | G48: =C48*0.005*0.3 -> 8550 | H48: =C48*0.03 -> 171000
A49: 43 | B49: Bùi Thị Kim Chi | C49: 5700000 | D49: =C49*0.02*0.75 -> 85500 | E49: =C49*0.02*0.25 -> 28500 | F49: =C49*0.005*0.7 -> 19950 | G49: =C49*0.005*0.3 -> 8550 | H49: =C49*0.03 -> 171000
A50: 44 | B50: Ngô Thị Ngọc Dung | C50: 5700000 | D50: =C50*0.02*0.75 -> 85500 | E50: =C50*0.02*0.25 -> 28500 | F50: =C50*0.005*0.7 -> 19950 | G50: =C50*0.005*0.3 -> 8550 | H50: =C50*0.03 -> 171000
B52: Tổng | C52: =SUM(C7:C51) -> 262610000 | D52: =SUM(D7:D51) -> 3939150 | E52: =SUM(E7:E51) -> 1313050 | F52: =SUM(F7:F51) -> 919135 | G52: =SUM(G7:G51) -> 393915 | H52: =SUM(H7:H51) -> 7878300
D53: =+D52+E52 -> 5252200
E54: Ngày 01 tháng 06 năm 2026
E55: Người lập
E60: Nguyễn Thị Cẩm Ly

Sheet Q1.2026
A1: Hung Phat Co., Ltd
J2: Theo quyết định số 61/QĐ-TLĐ ngày 29/07/2025
A3: Danh Sách Trích Nộp Phí Công Đoàn Quý 01 năm 2026 | J3: Thay đổi mức đóng đoàn phí hằng tháng là 0.5%
J4: bắt đầu có hiệu lực từ ngày 01/07/2025
A5: STT | B5: Họ & tên | C5: Mức lương đóng | D5: Trích đóng 2% | F5: Trích đóng 0.5% đoàn phí công đoàn | H5: Tổng cộng | J5: bắt đầu từ tháng 10 bỏ 9 mã số (2301, 2302, 2303, 2305, 2307, 2308, 2313, 2315, 2316)
D6: Công đoàn Cty giữ 75% | E6: Liên đoàn VN giữ 25% | F6: Công đoàn Cty giữ 70% | G6: Liên đoàn QTP giữ 30% | J6: V105 nghỉ thai sản
A7: 1 | B7: Trần Minh Thắng | C7: 5700000 | D7: =C7*0.02*0.75*3 -> 256500 | E7: =C7*0.02*0.25*3 -> 85500 | F7: =C7*0.005*0.7*3 -> 59850 | G7: =C7*0.005*0.3*3 -> 25650 | H7: =C7*0.03*3 -> 513000 | J7: Thêm 1518
A8: 2 | B8: Lê Hoàng Sỹ | C8: 5700000 | D8: =C8*0.02*0.75*3 -> 256500 | E8: =C8*0.02*0.25*3 -> 85500 | F8: =C8*0.005*0.7*3 -> 59850 | G8: =C8*0.005*0.3*3 -> 25650 | H8: =C8*0.03*3 -> 513000
A9: 3 | B9: Dương Hồng Loan | C9: 5700000 | D9: =C9*0.02*0.75*3 -> 256500 | E9: =C9*0.02*0.25*3 -> 85500 | F9: =C9*0.005*0.7*3 -> 59850 | G9: =C9*0.005*0.3*3 -> 25650 | H9: =C9*0.03*3 -> 513000
A10: 4 | B10: Lê Chí Thân | C10: 5700000 | D10: =C10*0.02*0.75*3 -> 256500 | E10: =C10*0.02*0.25*3 -> 85500 | F10: =C10*0.005*0.7*3 -> 59850 | G10: =C10*0.005*0.3*3 -> 25650 | H10: =C10*0.03*3 -> 513000
A11: 5 | B11: Nguyễn Văn Hây | C11: 5700000 | D11: =C11*0.02*0.75*3 -> 256500 | E11: =C11*0.02*0.25*3 -> 85500 | F11: =C11*0.005*0.7*3 -> 59850 | G11: =C11*0.005*0.3*3 -> 25650 | H11: =C11*0.03*3 -> 513000
A12: 6 | B12: Võ Huy Phong | C12: 5700000 | D12: =C12*0.02*0.75*3 -> 256500 | E12: =C12*0.02*0.25*3 -> 85500 | F12: =C12*0.005*0.7*3 -> 59850 | G12: =C12*0.005*0.3*3 -> 25650 | H12: =C12*0.03*3 -> 513000
A13: 7 | B13: Nguyễn Bá Thành | C13: 5700000 | D13: =C13*0.02*0.75*3 -> 256500 | E13: =C13*0.02*0.25*3 -> 85500 | F13: =C13*0.005*0.7*3 -> 59850 | G13: =C13*0.005*0.3*3 -> 25650 | H13: =C13*0.03*3 -> 513000
A14: 8 | B14: Vòng Và Tuấn | C14: 5700000 | D14: =C14*0.02*0.75*3 -> 256500 | E14: =C14*0.02*0.25*3 -> 85500 | F14: =C14*0.005*0.7*3 -> 59850 | G14: =C14*0.005*0.3*3 -> 25650 | H14: =C14*0.03*3 -> 513000
A15: 9 | B15: Nguyễn Nguyên Hùng | C15: 5700000 | D15: =C15*0.02*0.75*3 -> 256500 | E15: =C15*0.02*0.25*3 -> 85500 | F15: =C15*0.005*0.7*3 -> 59850 | G15: =C15*0.005*0.3*3 -> 25650 | H15: =C15*0.03*3 -> 513000
A16: 10 | B16: Trần Thị Ngọc Dung | C16: 5700000 | D16: =C16*0.02*0.75*3 -> 256500 | E16: =C16*0.02*0.25*3 -> 85500 | F16: =C16*0.005*0.7*3 -> 59850 | G16: =C16*0.005*0.3*3 -> 25650 | H16: =C16*0.03*3 -> 513000
A17: 11 | B17: Cao Đình Dương | C17: 5700000 | D17: =C17*0.02*0.75*3 -> 256500 | E17: =C17*0.02*0.25*3 -> 85500 | F17: =C17*0.005*0.7*3 -> 59850 | G17: =C17*0.005*0.3*3 -> 25650 | H17: =C17*0.03*3 -> 513000
A18: 12 | B18: Thái Trung Dũng | C18: 5700000 | D18: =C18*0.02*0.75*3 -> 256500 | E18: =C18*0.02*0.25*3 -> 85500 | F18: =C18*0.005*0.7*3 -> 59850 | G18: =C18*0.005*0.3*3 -> 25650 | H18: =C18*0.03*3 -> 513000
A19: 13 | B19: Trần Văn Hiếu | C19: 5700000 | D19: =C19*0.02*0.75*3 -> 256500 | E19: =C19*0.02*0.25*3 -> 85500 | F19: =C19*0.005*0.7*3 -> 59850 | G19: =C19*0.005*0.3*3 -> 25650 | H19: =C19*0.03*3 -> 513000
... A33: 27 | B33: Nguyễn Bá Quân | C33: 5700000 | D33: =C33*0.02*0.75*3 -> 256500 | E33: =C33*0.02*0.25*3 -> 85500 | F33: =C33*0.005*0.7*3 -> 59850 | G33: =C33*0.005*0.3*3 -> 25650 | H33: =C33*0.03*3 -> 513000
A34: 28 | B34: Sử Ngọc Quế | C34: 5700000 | D34: =C34*0.02*0.75*2 -> 171000 | E34: =C34*0.02*0.25*2 -> 57000 | F34: =C34*0.005*0.7*2 -> 39900 | G34: =C34*0.005*0.3*2 -> 17100 | H34: =C34*0.03*2 -> 342000
A35: 29 | B35: Ngô Thị Tuyết | C35: 5700000 | D35: =C35*0.02*0.75*3 -> 256500 | E35: =C35*0.02*0.25*3 -> 85500 | F35: =C35*0.005*0.7*3 -> 59850 | G35: =C35*0.005*0.3*3 -> 25650 | H35: =C35*0.03*3 -> 513000
A36: 30 | B36: Nguyễn Trường Vũ | C36: 20000000 | D36: =+'012026'!D36+'02026'!D36+'032026'!D36 -> 685500 | E36: =+'012026'!E36+'02026'!E36+'032026'!E36 -> 228500 | F36: =+'012026'!F36+'02026'!F36+'032026'!F36 -> 159950 | G36: =+'012026'!G36+'02026'!G36+'032026'!G36 -> 68550 | H36: =+'012026'!H36+'02026'!H36+'032026'!H36 -> 1371000 | I36: x
A37: 31 | B37: Lê Thị Thu Thảo | C37: 5700000 | D37: =C37*0.02*0.75*3 -> 256500 | E37: =C37*0.02*0.25*3 -> 85500 | F37: =C37*0.005*0.7*3 -> 59850 | G37: =C37*0.005*0.3*3 -> 25650 | H37: =C37*0.03*3 -> 513000
A38: 32 | B38: Lâm Nhật Quang | C38: 5700000 | D38: =C38*0.02*0.75*3 -> 256500 | E38: =C38*0.02*0.25*3 -> 85500 | F38: =C38*0.005*0.7*3 -> 59850 | G38: =C38*0.005*0.3*3 -> 25650 | H38: =C38*0.03*3 -> 513000
A39: 33 | B39: Bùi Xuân Mai Thảo | C39: 5700000 | D39: =C39*0.02*0.75*3 -> 256500 | E39: =C39*0.02*0.25*3 -> 85500 | F39: =C39*0.005*0.7*3 -> 59850 | G39: =C39*0.005*0.3*3 -> 25650 | H39: =C39*0.03*3 -> 513000
A40: 34 | B40: Nguyễn Quốc Cảnh | C40: 5700000 | D40: =C40*0.02*0.75*3 -> 256500 | E40: =C40*0.02*0.25*3 -> 85500 | F40: =C40*0.005*0.7*3 -> 59850 | G40: =C40*0.005*0.3*3 -> 25650 | H40: =C40*0.03*3 -> 513000
A41: 35 | B41: Huỳnh Thế Sơn | C41: 5700000 | D41: =C41*0.02*0.75*3 -> 256500 | E41: =C41*0.02*0.25*3 -> 85500 | F41: =C41*0.005*0.7*3 -> 59850 | G41: =C41*0.005*0.3*3 -> 25650 | H41: =C41*0.03*3 -> 513000
A42: 36 | B42: Nguyễn Thị Kỳ Duyên | C42: 5700000 | D42: =C42*0.02*0.75*3 -> 256500 | E42: =C42*0.02*0.25*3 -> 85500 | F42: =C42*0.005*0.7*3 -> 59850 | G42: =C42*0.005*0.3*3 -> 25650 | H42: =C42*0.03*3 -> 513000
A43: 37 | B43: Nguyễn Thị Mai Thi | C43: 5700000 | D43: =C43*0.02*0.75*3 -> 256500 | E43: =C43*0.02*0.25*3 -> 85500 | F43: =C43*0.005*0.7*3 -> 59850 | G43: =C43*0.005*0.3*3 -> 25650 | H43: =C43*0.03*3 -> 513000
A44: 38 | B44: Nông Hoàng Phát | C44: 5700000 | D44: =C44*0.02*0.75*3 -> 256500 | E44: =C44*0.02*0.25*3 -> 85500 | F44: =C44*0.005*0.7*3 -> 59850 | G44: =C44*0.005*0.3*3 -> 25650 | H44: =C44*0.03*3 -> 513000
A45: 39 | B45: Lê Thị Nhã Mi | C45: 0 | D45: =C45*0.02*0.75*3 -> 0 | E45: =C45*0.02*0.25*3 -> 0 | F45: =C45*0.005*0.7*3 -> 0 | G45: =C45*0.005*0.3*3 -> 0 | H45: =C45*0.03*3 -> 0 | I45: Nghỉ thai sản
A46: 40 | B46: Nguyễn Thị Cẩm Ly | C46: 5700000 | D46: =C46*0.02*0.75*3 -> 256500 | E46: =C46*0.02*0.25*3 -> 85500 | F46: =C46*0.005*0.7*3 -> 59850 | G46: =C46*0.005*0.3*3 -> 25650 | H46: =C46*0.03*3 -> 513000
A47: 41 | B47: Lê Thị Hiếu Thư | C47: 5700000 | D47: =C47*0.02*0.75*3 -> 256500 | E47: =C47*0.02*0.25*3 -> 85500 | F47: =C47*0.005*0.7*3 -> 59850 | G47: =C47*0.005*0.3*3 -> 25650 | H47: =C47*0.03*3 -> 513000
A48: 42 | B48: Bùi Thị Kim Chi | C48: 5700000 | D48: =C48*0.02*0.75*3 -> 256500 | E48: =C48*0.02*0.25*3 -> 85500 | F48: =C48*0.005*0.7*3 -> 59850 | G48: =C48*0.005*0.3*3 -> 25650 | H48: =C48*0.03*3 -> 513000
A49: 43 | B49: Ngô Thị Ngọc Dung | C49: 5700000 | D49: =C49*0.02*0.75 -> 85500 | E49: =C49*0.02*0.25 -> 28500 | F49: =C49*0.005*0.7 -> 19950 | G49: =C49*0.005*0.3 -> 8550 | H49: =C49*0.03 -> 171000
B51: Tổng | C51: =SUM(C7:C50)*3 -> 787830000 | D51: =SUM(D7:D50) -> 11346450 | E51: =SUM(E7:E50) -> 3782150 | F51: =SUM(F7:F50) -> 2647505 | G51: =SUM(G7:G50) -> 1134645 | H51: =SUM(H7:H50) -> 22692900
E53: Ngày 01 tháng 03 năm 2026
E54: Người lập
E59: Nguyễn Thị Cẩm Ly

Sheet TC 
A1: CÔNG TY TNHH THIẾT KẾ XÂY DỰNG VÀ THƯƠNG MẠI HƯNG PHÁT
A2: Địa Chỉ: 153G Lũy Bán Bích, Phường Tân Thới Hòa, Quận Tân Phú, TP Hồ Chí Minh
A3: Mã Số Thuế: 0309178743
A6: BẢNG TÍNH KINH PHÍ, ĐOÀN PHÍ CÔNG ĐOÀN
A9: Tháng/ Năm Phát Sinh | B9: Số Lao Động | C9: Quỹ lương làm căn cứ nộp BHXH | D9: Nộp 2% Kinh Phí Công Đoàn | E9: Nhận 75% KPCĐ trên 2% đã nộp | F9: Thực đóng | G9: Công đoàn Cty giữ 70% Đoàn phí | H9: Nộp 30% của 0.5% Đoàn Phí
A10: (1) | B10: (2) | C10: (3) | D10: (4)=(3) x 2% | E10: (5)=(4) x 75% | F10: (6)=(4) - (5) | G10: (7)=(3) x 0.5% x 70% | H10: (7)=(3) x 0.5% x 30%
A11: Tháng 1/2026 | B11: 41 | C11: =+'012026'!C50 -> 242610000 | D11: =+C11*0.02 -> 4852200 | E11: =+(C11*2%)*0.75 -> 3639150 | F11: =+D11-E11 -> 1213050 | G11: =+C11*0.5%*0.7 -> 849135 | H11: =+(C11*0.5%)*0.3 -> 363915
A12: Tháng 2/2026 | B12: 41 | C12: =+'02026'!C50 -> 256910000 | D12: =+C12*0.02 -> 5138200 | E12: =+(C12*2%)*0.75 -> 3853650 | F12: =+D12-E12 -> 1284550 | G12: =+C12*0.5%*0.7 -> 899185 | H12: =+(C12*0.5%)*0.3 -> 385365
A13: Tháng 3/2026 | B13: 41 | C13: =+'032026'!C51 -> 256910000 | D13: =+C13*0.02 -> 5138200 | E13: =+(C13*2%)*0.75 -> 3853650 | F13: =+D13-E13 -> 1284550 | G13: =+C13*0.5%*0.7 -> 899185 | H13: =+(C13*0.5%)*0.3 -> 385365
A14: Tháng 4/2026 | B14: 42 | C14: =+'042026'!C52 -> 262610000 | D14: =+C14*0.02 -> 5252200 | E14: =+(C14*2%)*0.75 -> 3939150 | F14: =+D14-E14 -> 1313050 | G14: =+C14*0.5%*0.7 -> 919135 | H14: =+(C14*0.5%)*0.3 -> 393915
A15: Tháng 5/2026 | B15: 43 | C15: =+'052026'!C52 -> 268310000 | D15: =+C15*0.02 -> 5366200 | E15: =+(C15*2%)*0.75 -> 4024650 | F15: =+D15-E15 -> 1341550 | G15: =+C15*0.5%*0.7 -> 939085 | H15: =+(C15*0.5%)*0.3 -> 402465
A16: Tháng 6/2026 | B16: 42 | C16: =+'062026'!C52 -> 262610000 | D16: =+C16*0.02 -> 5252200 | E16: =+(C16*2%)*0.75 -> 3939150 | F16: =+D16-E16 -> 1313050 | G16: =+C16*0.5%*0.7 -> 919135 | H16: =+(C16*0.5%)*0.3 -> 393915
A20: TỔNG CỘNG | C20: =SUM(C11:C19) -> 1549960000 | D20: =SUM(D11:D19) -> 30999200 | E20: =SUM(E11:E19) -> 23249400 | F20: =SUBTOTAL(9,F11:F18) -> 7749800 | G20: =SUBTOTAL(9,G11:G18) -> 5424860 | H20: =SUBTOTAL(9,H11:H19) -> 2324940
E22: =+D17*0.25% -> 0
